Workbook

Sheet SOMMAIRE
A1: Travailleurs handicapés
B2: Nom de l'onglet | C2: Contient des données sur l'égalité professionnelle entre les femmes et les hommes
A3: ='Figure 1'!A1 -> Part des agents ou salariés reconnus comme travailleurs handicapés ou percevant l'allocation aux adultes handicapés (AAH) | B3: Figure 1
A4: ='Figure 2'!A1 -> Part des agents ou salariés reconnus comme travailleurs handicapés ou percevant l'allocation aux adultes handicapés (AAH) à temps partiel et quotité de travail en EQTP | B4: Figure 2
A5: ='Figure 3'!A1 -> Part des femmes parmi les agents ou salariés reconnus comme travailleurs handicapés ou percevant l'allocation aux adultes handicapés (AAH) | B5: Figure 3 | C5: oui
A6: ='Figure 4'!A1 -> Bénéficiaires de l'obligation d'emploi en faveur des travailleurs handicapés dans les trois versants de la fonction publique | B6: Figure 4
A7: ='Figure 5'!A1 -> Bénéficiaires de l'obligation d'emploi en faveur des travailleurs handicapés par type d'employeur de la fonction publique | B7: Figure 5
A8: ='Figure 6'!A1 -> Part des femmes parmi les bénéficiaires de l'obligation d'emploi en faveur des travailleurs handicapés par type d'employeur de la fonction publique | B8: Figure 6 | C8: oui
A9: ='Figure 7'!A1 -> Bénéficiaires de l'obligation d'emploi en faveur des travailleurs handicapés par ministères au 31 décembre 2024 | B9: Figure 7 | C9: oui
A10: ='Figure 8'!A1 -> Répartition des bénéficiaires de l'obligation d'emploi en faveur des travailleurs handicapés par statut et par sexe dans les trois versants de la fonction publique au 31 décembre 2024 | B10: Figure 8 | C10: oui
A11: ='Figure 9'!A1 -> Bénéficiaires de l'obligation d'emploi en faveur des travailleurs handicapés occupant un emploi particulier(1) par sexe et par versant de la fonction publique | B11: Figure 9 | C11: oui

Sheet Figure 1
A1: Part des agents ou salariés reconnus comme travailleurs handicapés ou percevant l'allocation aux adultes handicapés (AAH)
A2: en %
B3: 2014 | C3: 2015 | D3: 2016 | E3: 2017 | F3: 2018 | G3: 2019 | H3: 2020 | I3: 2021 | J3: 2022 | K3: 2023 | L3: 2024 | M3: 2025
A4: FPE | B4: 2.44 | C4: 2.92 | D4: 3.1 | E4: 2.92 | F4: 2.5 | G4: 3.63 | H4: 3.29 | I4: 3.450102 | J4: 3.617558 | K4: 4.252358 | L4: 4.833479 | M4: 4.755199
A5: FPT | B5: 4.74 | C5: 4.52 | D5: 4.62 | E5: 5.41 | F5: 4.36 | G5: 4.67 | H5: 5.06 | I5: 4.916966 | J5: 5.738518 | K5: 5.839301 | L5: 6.329685 | M5: 6.884807
A6: FPH | B6: 2.61 | C6: 3.33 | D6: 3.63 | E6: 4.06 | F6: 4.33 | G6: 4.62 | H6: 3.9 | I6: 3.529707 | J6: 4.345766 | K6: 4.532367 | L6: 5.084891 | M6: 5.294558
A7: Ensemble de la fonction publique | B7: 3.28 | C7: 3.56 | D7: 3.73 | E7: 4.01 | F7: 3.52 | G7: 4.18 | H7: 4.01 | I7: 3.948971 | J7: 4.472709 | K7: 4.844558 | L7: 5.392189 | M7: 5.568929
A8: Secteur privé | B8: 3.54 | C8: 3.7 | D8: 3.72 | E8: 3.77 | F8: 3.89 | G8: 3.76 | H8: 3.67 | I8: 3.780565 | J8: 4.055449 | K8: 4.32242 | L8: 4.775638 | M8: 4.950287
A9: Ensemble | B9: 3.48 | C9: 3.66 | D9: 3.73 | E9: 3.82 | F9: 3.81 | G9: 3.86 | H9: 3.75 | I9: 3.819836 | J9: 4.152114 | K9: 4.444086 | L9: 4.919723 | M9: 5.091297
A10: Source : Insee, enquêtes Emploi, Traitement DGAFP - Sdessi.
A11: Champ : France (hors Mayotte), salariés, hors stagiaires et bénéficiaires de contrats aidés.
A12: Lecture : 5,6 % des agents de la fonction publique sont reconnus comme étant travailleurs handicapés ou bénéficiaires l'allocation aux adultes handicapés (AAH) en 2025, contre 3,3 % en 2014.
A13: Note : L’affectation des agents publics à leur versant a été améliorée dans l'enquête emploi ce qui entraîne des différences par rapport aux résultats par versant des publications antérieures sur l’ensemble de la période 2021 à 2025. Notamment les accompagnants d’élèves en situation de handicap (AESH), qui figuraient initialement dans la FPT et la FPH sont, après retraitement, désormais comptabilisés au sein de la FPE.

Sheet Figure 2
A1: Part des agents ou salariés reconnus comme travailleurs handicapés ou percevant l'allocation aux adultes handicapés (AAH) à temps partiel et quotité de travail en EQTP
A3: en % | C3: 2014 | D3: 2015 | E3: 2016 | F3: 2017 | G3: 2018 | H3: 2019 | I3: 2020 | J3: 2021 | K3: 2022 | L3: 2023 | M3: 2024 | N3: 2025
A4: FPE | B4: Part des agents à temps partiel | C4: 23.28 | D4: 23.8 | E4: 24.03 | F4: 28.78 | G4: 39.83 | H4: 29.92 | I4: 33.92 | J4: 34.6789 | K4: 36.97203 | L4: 36.77634 | M4: 32.58293 | N4: 32.84471
B5: Quotité moyenne de travail en EQTP(*) | C5: 0.92 | D5: 0.93 | E5: 0.93 | F5: 0.89 | G5: 0.83 | H5: 0.91 | I5: 0.89 | J5: 0.871529 | K5: 0.856297 | L5: 0.852287 | M5: 0.877255 | N5: 0.87368
A6: FPT | B6: Part des agents à temps partiel | C6: 35.32 | D6: 35.96 | E6: 36.4 | F6: 31.65 | G6: 32.76 | H6: 32.28 | I6: 36.23 | J6: 29.55201 | K6: 27.58964 | L6: 28.59274 | M6: 31.58009 | N6: 28.03937
B7: Quotité moyenne de travail en EQTP(*) | C7: 0.85 | D7: 0.81 | E7: 0.84 | F7: 0.84 | G7: 0.83 | H7: 0.81 | I7: 0.82 | J7: 0.88817 | K7: 0.897648 | L7: 0.889875 | M7: 0.881401 | N7: 0.89596
A8: FPH | B8: Part des agents à temps partiel | C8: 41.29 | D8: 25.07 | E8: 21.04 | F8: 32.89 | G8: 26.18 | H8: 33.85 | I8: 33.11 | J8: 29.24379 | K8: 23.44254 | L8: 29.14211 | M8: 28.23424 | N8: 26.28243
B9: Quotité moyenne de travail en EQTP(*) | C9: 0.85 | D9: 0.91 | E9: 0.9 | F9: 0.87 | G9: 0.9 | H9: 0.87 | I9: 0.92 | J9: 0.902937 | K9: 0.923119 | L9: 0.898688 | M9: 0.901363 | N9: 0.925328
A10: Ensemble de la fonction publique | B10: Part des agents à temps partiel | C10: 32.23 | D10: 29.42 | E10: 28.77 | F10: 30.96 | G10: 33.41 | H10: 31.67 | I10: 34.77 | J10: 31.60303 | K10: 30.26686 | L10: 32.01016 | M10: 31.37191 | N10: 29.65073
B11: Quotité moyenne de travail en EQTP(*) | C11: 0.87 | D11: 0.87 | E11: 0.89 | F11: 0.86 | G11: 0.85 | H11: 0.86 | I11: 0.86 | J11: 0.883981 | K11: 0.887285 | L11: 0.876309 | M11: 0.883404 | N11: 0.892427
A12: Secteur privé | B12: Part des salariés à temps partiel | C12: 33.72 | D12: 32 | E12: 34.23 | F12: 33.97 | G12: 35.29 | H12: 33.8 | I12: 34.77 | J12: 36.01689 | K12: 33.59046 | L12: 33.50269 | M12: 35.27621 | N12: 36.74329
B13: Quotité moyenne de travail en EQTP(*) | C13: 0.83 | D13: 0.84 | E13: 0.81 | F13: 0.81 | G13: 0.79 | H13: 0.81 | I13: 0.81 | J13: 0.837414 | K13: 0.848528 | L13: 0.852405 | M13: 0.84314 | N13: 0.836607
A14: Ensemble | B14: Part des agents ou salariés à temps partiel | C14: 33.39 | D14: 31.42 | E14: 33 | F14: 33.26 | G14: 34.9 | H14: 33.27 | I14: 34.77 | J14: 34.95282 | K14: 32.76104 | L14: 33.12357 | M14: 34.27617 | N14: 34.97499
B15: Quotité moyenne de travail en EQTP(*) | C15: 0.84 | D15: 0.85 | E15: 0.83 | F15: 0.82 | G15: 0.81 | H15: 0.82 | I15: 0.83 | J15: 0.84864 | K15: 0.8582 | L15: 0.858477 | M15: 0.853454 | N15: 0.850524
A16: Source : Insee, enquête Emploi, Traitement DGAFP - Sdessi,
A17: Champ : France (hors Mayotte), salariés, hors stagiaires et bénéficiaires de contrats aidés.
A18: Lecture : 30 % des agents de la fonction publique reconnus comme étant travailleurs handicapés ou bénéficiaires l'allocation aux adultes handicapés (AAH) travaillent à temps partiel en 2025.
A19: (*) La quotité moyenne de travail est ici celle de l'ensemble des agents/salariés reconnus comme travailleurs handicapés (temps complet ou temps partiel). L'estimation des EQTP est réalisée à partir d'une proratisation de la quotité du temps de travail hebdomadaire et du temps du contrat pour les salariés en CDD, les agents contractuels ou les intérimaires.
A20: Note : L’affectation des agents publics à leur versant a été améliorée dans l'enquête emploi ce qui entraîne des différences par rapport aux résultats par versant des publications antérieures sur l’ensemble de la période 2021 à 2025. Notamment les accompagnants d’élèves en situation de handicap (AESH), qui figuraient initialement dans la FPT et la FPH sont, après retraitement, désormais comptabilisés au sein de la FPE.

Sheet Figure 3
A1: Part des femmes parmi les agents ou salariés reconnus comme travailleurs handicapés ou percevant l'allocation aux adultes handicapés (AAH)
A3: en % | C3: 2014 | D3: 2015 | E3: 2016 | F3: 2017 | G3: 2018 | H3: 2019 | I3: 2020 | J3: 2021 | K3: 2022 | L3: 2023 | M3: 2024 | N3: 2025
A4: FPE | B4: Part des femmes parmis les agents reconnus comme travailleurs handicapés ou percevant l'allocation aux adultes handicapés | C4: 63.49 | D4: 65.06 | E4: 55.84 | F4: 59.6 | G4: 67.14 | H4: 60.6 | I4: 63.84 | J4: 72.23561 | K4: 71.21718 | L4: 66.36786 | M4: 66.57264 | N4: 65.1775
B5: Part des femmes parmis l'ensemble des agents | C5: 55.64 | D5: 57.22 | E5: 57.17 | F5: 55.84 | G5: 56.27 | H5: 57.61 | I5: 58.47 | J5: 58.54426 | K5: 58.37067 | L5: 58.21179 | M5: 58.33356 | N5: 59.51531
A6: FPT | B6: Part des femmes parmis les agents reconnus comme travailleurs handicapés ou percevant l'allocation aux adultes handicapés | C6: 54.75 | D6: 61.23 | E6: 60.51 | F6: 60.9 | G6: 63.83 | H6: 58.24 | I6: 63.19 | J6: 62.60661 | K6: 62.23173 | L6: 60.2265 | M6: 64.41482 | N6: 61.60607
B7: Part des femmes parmis l'ensemble des agents | C7: 62.04 | D7: 63.15 | E7: 63.41 | F7: 64.98 | G7: 65.14 | H7: 63.57 | I7: 65.06 | J7: 63.37043 | K7: 60.93833 | L7: 59.43811 | M7: 61.58408 | N7: 61.61615
A8: FPH | B8: Part des femmes parmis les agents reconnus comme travailleurs handicapés ou percevant l'allocation aux adultes handicapés | C8: 68.2 | D8: 72.76 | E8: 75.6 | F8: 71.74 | G8: 65.97 | H8: 74.78 | I8: 81.41 | J8: 74.47045 | K8: 82.63452 | L8: 78.13484 | M8: 76.91502 | N8: 76.15255
B9: Part des femmes parmis l'ensemble des agents | C9: 78.08 | D9: 79.86 | E9: 79.52 | F9: 78.15 | G9: 78.18 | H9: 78.87 | I9: 79.69 | J9: 79.52787 | K9: 78.10963 | L9: 77.95028 | M9: 78.90852 | N9: 78.97083
A10: Ensemble de la fonction publique | B10: Part des femmes parmis les agents reconnus comme travailleurs handicapés ou percevant l'allocation aux adultes handicapés | C10: 59.87 | D10: 64.76 | E10: 61.46 | F10: 62.61 | G10: 65.42 | H10: 62.65 | I10: 67.05 | J10: 68.68925 | K10: 69.66149 | L10: 66.07959 | M10: 67.63855 | N10: 65.74506
B11: Part des femmes parmis l'ensemble des agents | C11: 62.35 | D11: 63.65 | E11: 63.63 | F11: 63.51 | G11: 63.64 | H11: 63.84 | I11: 64.81 | J11: 64.34152 | K11: 63.28034 | L11: 62.59146 | M11: 63.506 | N11: 64.01125
A12: Secteur privé | B12: Part des femmes parmis les salariés reconnus comme travailleurs handicapés ou percevant l'allocation aux adultes handicapés | C12: 43.07 | D12: 47.79 | E12: 46.52 | F12: 44.66 | G12: 46.03 | H12: 48.01 | I12: 45.85 | J12: 50.51706 | K12: 49.13601 | L12: 48.02562 | M12: 51.13258 | N12: 50.88749
B13: Part des femmes parmis l'ensemble des salariées | C13: 46.86 | D13: 46.77 | E13: 46.68 | F13: 46.49 | G13: 46.75 | H13: 46.89 | I13: 46.34 | J13: 46.30995 | K13: 46.71535 | L13: 46.71877 | M13: 46.11419 | N13: 46.08968
A14: Ensemble | B14: Part des femmes parmis les agents et salariés reconnus comme travailleurs handicapés ou percevant l'allocation aux adultes handicapés | C14: 46.74 | D14: 51.52 | E14: 49.86 | F14: 48.87 | G14: 50.12 | H14: 51.68 | I14: 51.14 | J14: 54.89793 | K14: 54.25822 | L14: 52.61155 | M14: 55.36039 | N14: 54.59176
B15: Part des femmes parmis l'ensemble des agents et salariés | C15: 50.5 | D15: 50.62 | E15: 50.53 | F15: 50.29 | G15: 50.53 | H15: 50.8 | I15: 50.75 | J15: 50.51476 | K15: 50.5529 | L15: 50.41734 | M15: 50.17858 | N15: 50.17463
A16: Source : Insee, enquête Emploi, Traitement DGAFP - Sdessi.
A17: Champ : France (hors Mayotte), salariés, hors stagiaires et bénéficiaires de contrats aidés.
A18: Lecture : En 2025, 66 % des agents de la fonction publique reconnus comme étant travailleurs handicapés ou bénéficiaires l'allocation aux adultes handicapés (AAH) sont des femmes.
A19: Note : L’affectation des agents publics à leur versant a été améliorée dans l'enquête emploi ce qui entraîne des différences par rapport aux résultats par versant des publications antérieures sur l’ensemble de la période 2021 à 2025. Notamment les accompagnants d’élèves en situation de handicap (AESH), qui figuraient initialement dans la FPT et la FPH sont, après retraitement, désormais comptabilisés au sein de la FPE.

Sheet Figure 4
A1: Bénéficiaires de l'obligation d'emploi en faveur des travailleurs handicapés dans les trois versants de la fonction publique
C3: 2009 | D3: 2010 | E3: 2011 | F3: 2012 | G3: 2013 | H3: 2014 | I3: 2015 | J3: 2016 | K3: 2017 | L3: 2018 | M3: 2019 | N3: 2020 | O3: 2021 | P3: 2022 | Q3: 2023 | R3: 2024
A4: FPE | B4: Nombre de bénéficiaires (en milliers) | C4: 48.9 | D4: 55.3 | E4: 61.4 | F4: 64.4 | G4: 69.6 | H4: 74.2 | I4: 79.5 | J4: 84.1 | K4: 88.8 | L4: 92.2 | M4: 92.7 | N4: 86.2 | O4: 87.397 | P4: 94.886 | Q4: 101.906 | R4: 108.205
B5: Taux d'emploi direct (en %) | C5: 2.5 | D5: 2.8 | E5: 3.2 | F5: 3.4 | G5: 3.7 | H5: 4 | I5: 4.2 | J5: 4.3 | K5: 4.5 | L5: 4.7 | M5: 4.7 | N5: 4.4 | O5: 4.36 | P5: 4.64 | Q5: 4.86 | R5: 5.2842884
A6: dont FPE (hors enseignement) | B6: Nombre de bénéficiaires (en milliers) | C6: 36.4 | D6: 39.5 | E6: 41.7 | F6: 42.1 | G6: 43.2 | H6: 47.9 | I6: 48.9 | J6: 50 | K6: 52.9 | L6: 54.6 | M6: 56.7 | N6: 52.1 | O6: 52.673 | P6: 55.462 | Q6: 58.176 | R6: 60.706
B7: Taux d'emploi direct (en %) | C7: 4.7 | D7: 4.8 | E7: 5.1 | F7: 5.2 | G7: 5.4 | H7: 5.1 | I7: 5.2 | J7: 5.3 | K7: 5.6 | L7: 5.7 | M7: 6 | N7: 5.5 | O7: 5.48 | P7: 5.41 | Q7: 5.66 | R7: 5.8597656
A8: FPT | B8: Nombre de bénéficiaires (en milliers) | C8: 66.9 | D8: 71.9 | E8: 76.9 | F8: 82.6 | G8: 88.5 | H8: 94.7 | I8: 98.9 | J8: 103.6 | K8: 106.1 | L8: 109.8 | M8: 111.5 | N8: 112.2 | O8: 114.457 | P8: 118.253 | Q8: 125.586 | R8: 134.272
B9: Taux d'emploi direct (en %) | C9: 4.5 | D9: 4.8 | E9: 5 | F9: 5.3 | G9: 5.6 | H9: 5.9 | I9: 6 | J9: 6.3 | K9: 6.4 | L9: 6.6 | M9: 6.7 | N9: 6.7 | O9: 6.72 | P9: 6.87 | Q9: 7.23 | R9: 7.681113
A10: FPH | B10: Nombre de bénéficiaires (en milliers) | C10: 42.1 | D10: 44.5 | E10: 46.1 | F10: 47.6 | G10: 49.6 | H10: 50.7 | I10: 51.5 | J10: 51.9 | K10: 53.3 | L10: 53.9 | M10: 54.5 | N10: 54.6 | O10: 55.376 | P10: 56.722 | Q10: 59.658 | R10: 64.433
B11: Taux d'emploi direct (en %) | C11: 4.6 | D11: 4.7 | E11: 4.9 | F11: 4.9 | G11: 5.1 | H11: 5.1 | I11: 5.2 | J11: 5.3 | K11: 5.4 | L11: 5.5 | M11: 5.5 | N11: 5.5 | O11: 5.53 | P11: 5.62 | Q11: 5.88 | R11: 6.2625624
A12: Ensemble fonction publique | B12: Nombre de bénéficiaires (en milliers) | C12: 157.9 | D12: 171.7 | E12: 184.4 | F12: 194.6 | G12: 207.8 | H12: 219.6 | I12: 229.9 | J12: 239.6 | K12: 248.2 | L12: 255.9 | M12: 258.6 | N12: 253.1 | O12: 257.23 | P12: 269.861 | Q12: 287.15 | R12: 306.91
B13: Taux d'emploi direct (en %) | C13: 3.7 | D13: 3.9 | E13: 4.2 | F13: 4.4 | G13: 4.7 | H13: 4.9 | I13: 5.1 | J13: 5.2 | K13: 5.4 | L13: 5.6 | M13: 5.6 | N13: 5.5 | O13: 5.46 | P13: 5.6497739 | Q13: 5.92 | R13: 6.3613379
A14: Source : Fonds pour l'insertion des personnes handicapées dans la fonction publique (FIPHFP).
A15: Champ : Employeurs publics d’au moins 20 agents à temps plein ou leur équivalent, hors aides-soignants, infirmiers et emplois particuliers (stagiaires handicapés accueillis pour des stages pratiques)
A16: Lecture : En 2024, le taux d'emploi direct dans la fonction publique de l'État était de 5,3 %.
A17: Note 1 : Le taux d’emploi direct est le rapport entre le nombre de bénéficiaires de l’obligation d’emploi et l’effectif total rémunéré.
A18: Note 2 : Ces données sont celles déclarées par les employeurs, Le nombre de déclarants évoluant chaque année, cela peut entraîner des évolutions du nombre de bénéficiaires de l'obligation d'emploi plus ou moins importantes d'une année sur l'autre.

Sheet Figure 5
A1: Bénéficiaires de l'obligation d'emploi en faveur des travailleurs handicapés par type d'employeur de la fonction publique
C2: 2011 | D2: 2012 | E2: 2013 | F2: 2014 | G2: 2015 | H2: 2016 | I2: 2017 | J2: 2018 | K2: 2019 | L2: 2020 | M2: 2021 | N2: 2022 | O2: 2023 | P2: 2024
A3: Ministères | B3: Effectif total rémunéré (en milliers) | C3: 1733.4 | D3: 1712 | E3: 1705.6 | F3: 1524.2 | G3: 1562.8 | H3: 1609 | I3: 1609 | J3: 1598 | K3: 1611.3 | L3: 1585.4 | M3: 1618.169 | N3: 1591.901 | O3: 1642.462 | P3: 1589.684
A4: Établissements publics(1) | B4: Effectif total rémunéré (en milliers) | C4: 192.9 | D4: 196 | E4: 203.9 | F4: 347.2 | G4: 350.8 | H4: 352.9 | I4: 367.3 | J4: 366.7 | K4: 364.4 | L4: 374.4 | M4: 387.135 | N4: 454.948 | O4: 455.051 | P4: 457.99
A5: FPE | B5: Effectif total rémunéré (en milliers) | C5: 1926.4 | D5: 1908.1 | E5: 1909.4 | F5: 1871.4 | G5: 1913.6 | H5: 1961.9 | I5: 1976.3 | J5: 1964.7 | K5: 1975.6 | L5: 1959.8 | M5: 2005.304 | N5: 2046.849 | O5: 2097.513 | P5: 2047.674
A6: Dont : FPE (hors enseignement) | B6: Effectif total rémunéré (en milliers) | C6: 812.8 | D6: 805.7 | E6: 805.6 | F6: 936.4 | G6: 937.4 | H6: 937.6 | I6: 952.6 | J6: 951 | K6: 948.9 | L6: 947.6 | M6: 961.142 | N6: 1025.799 | O6: 1028.425 | P6: 1035.98
A7: Collectivités territoriales | B7: Effectif total rémunéré (en milliers) | C7: 1184.8 | D7: 1194.2 | E7: 1206.3 | F7: 1217.8 | G7: 1224.3 | H7: 1221.3 | I7: 1212.4 | J7: 1205.2 | K7: 1198.9 | L7: 1207.5 | M7: 1219.927 | N7: 1229.116 | O7: 1236.74 | P7: 1242.785
A8: EPA locaux | B8: Effectif total rémunéré (en milliers) | C8: 350.1 | D8: 362.1 | E8: 378.8 | F8: 399 | G8: 412.2 | H8: 432.4 | I8: 439.3 | J8: 457.3 | K8: 464.1 | L8: 476 | M8: 483.149 | N8: 492.077 | O8: 497.65 | P8: 505.295
A9: FPT | B9: Effectif total rémunéré (en milliers) | C9: 1534.8 | D9: 1556.3 | E9: 1585.1 | F9: 1616.8 | G9: 1636.5 | H9: 1653.7 | I9: 1651.6 | J9: 1662.5 | K9: 1663.1 | L9: 1683.5 | M9: 1703.076 | N9: 1721.193 | O9: 1734.39 | P9: 1748.08
A10: Hopitaux | B10: Effectif total rémunéré (en milliers) | C10: 820.9 | D10: 849.8 | E10: 859.4 | F10: 867 | G10: 866.1 | H10: 863.9 | I10: 862.9 | J10: 861.9 | K10: 860.9 | L10: 871 | M10: 876.587 | N10: 883.076 | O10: 886.424 | P10: 903.39
A11: Autres | B11: Effectif total rémunéré (en milliers) | C11: 129.8 | D11: 115.4 | E11: 117.4 | F11: 121 | G11: 120 | H11: 122.2 | I11: 123.8 | J11: 123.6 | K11: 121.5 | L11: 125.3 | M11: 124.962 | N11: 125.374 | O11: 125.223 | P11: 125.47
A12: FPH | B12: Effectif total rémunéré (en milliers) | C12: 950.7 | D12: 965.2 | E12: 976.8 | F12: 988 | G12: 986.2 | H12: 986.1 | I12: 986.8 | J12: 985.5 | K12: 982.5 | L12: 996.4 | M12: 1001.549 | N12: 1008.45 | O12: 1011.647 | P12: 1028.86
A13: Ensemble FP | B13: Effectif total rémunéré (en milliers) | C13: 4411.9 | D13: 4429.5 | E13: 4471.4 | F13: 4476.2 | G13: 4536.3 | H13: 4601.7 | I13: 4614.7 | J13: 4612.7 | K13: 4621.1 | L13: 4639.6 | M13: 4709.929 | N13: 4776.492 | O13: 4843.55 | P13: 4824.614
A14: Ministères | B14: Nombre de bénéficiaires (en milliers) | C14: 53.5 | D14: 56.2 | E14: 60.5 | F14: 61.1 | G14: 65.7 | H14: 69.3 | I14: 72 | J14: 74.3 | K14: 74.5 | L14: 66.8 | M14: 66.05 | N14: 70.055 | O14: 75.79 | P14: 80.003
... A35: Ensemble fonction publique | B35: Taux d'emploi direct (en %) | C35: 4.2 | D35: 4.4 | E35: 4.6 | F35: 4.9 | G35: 5.1 | H35: 5.2 | I35: 5.4 | J35: 5.5 | K35: 5.6 | L35: 5.5 | M35: 5.5 | N35: 5.6 | O35: 5.9 | P35: 6.4
A36: Source : Fonds pour l'insertion des personnes handicapées dans la fonction publique (FIPHFP).
A37: Champ : Employeurs publics d’au moins 20 agents à temps plein ou leur équivalent, hors aides-soignants, infirmiers et emplois particuliers (stagiaires handicapés accueillis pour des stages pratiques).
A38: Lecture : En 2024, il y avait 306 900 bénéficiaires de l'obligation d'emploi en faveur des travailleurs handicapés dans l'ensemble de la fonction publique.
A39: Note 1 : Le taux d’emploi direct est le rapport entre le nombre de bénéficiaires de l’obligation d’emploi et l’effectif total rémunéré.
A40: Note 2 : Ces données sont celles déclarées par les employeurs, Le nombre de déclarants évoluant chaque année, cela peut entraîner des évolutions du nombre de bénéficiaires de l'obligation d'emploi plus ou moins importantes d'une année sur l'autre.
A41: (1) Depuis 2014, les universités qui étaient auparavant rattachées au ministère de l'Éducation nationale sont comptabilisées parmi les établissements publics.

Sheet Figure 6
A1: Part des femmes parmi les bénéficiaires de l'obligation d'emploi en faveur des travailleurs handicapés par type d'employeur de la fonction publique
C2: 2011 | D2: 2012 | E2: 2013 | F2: 2014 | G2: 2015 | H2: 2016 | I2: 2017 | J2: 2018 | K2: 2019 | L2: 2020 | M2: 2021 | N2: 2022 | O2: 2023 | P2: 2024
A3: Ministères | B3: Part des femmes bénéficiaires (en %) | C3: 48.6 | D3: 49.6 | E3: 52.2 | F3: 54.1 | G3: 57.5 | H3: 60.39 | I3: 61.09 | J3: 61.27 | K3: 61.4 | L3: 61 | M3: 64.15 | N3: 66.32 | O3: 67.9 | P3: 69.56
A4: Établissements publics(1) | B4: Part des femmes bénéficiaires (en %) | C4: 53.9 | D4: 57.6 | E4: 57.6 | F4: 58.6 | G4: 59.8 | H4: 60.81 | I4: 63.42 | J4: 64.52 | K4: 65.2 | L4: 66 | M4: 68.29 | N4: 68.22 | O4: 68.4 | P4: 68.89
A5: FPE | B5: Part des femmes bénéficiaires (en %) | C5: 47.7 | D5: 50.6 | E5: 52.9 | F5: 54.9 | G5: 57.9 | H5: 60.46 | I5: 61.49 | J5: 61.9 | K5: 62.1 | L5: 69 | M5: 65.16 | N5: 66.82 | O5: 68.1 | P5: 69.39
A6: Dont : FPE (hors enseignement) | B6: Part des femmes bénéficiaires (en %) | C6: 40 | D6: 41.3 | E6: 42.3 | F6: 44.6 | G6: 47 | H6: 49.26 | I6: 50.73 | J6: 50.7 | K6: 52.5 | L6: 53 | M6: 56.96 | N6: 58.57 | O6: 59.8 | P6: 60.93
A7: Collectivités territoriales | B7: Part des femmes bénéficiaires (en %) | C7: 49.2 | D7: 51.2 | E7: 52.6 | F7: 53.4 | G7: 55.6 | H7: 56.85 | I7: 58.09 | J7: 59.5 | K7: 60.9 | L7: 62 | M7: 63.33 | N7: 64.4 | O7: 65.3 | P7: 66.11
A8: EPA locaux | B8: Part des femmes bénéficiaires (en %) | C8: 44.9 | D8: 44.6 | E8: 45.9 | F8: 47.7 | G8: 49.7 | H8: 51.66 | I8: 52.13 | J8: 53.4 | K8: 54.6 | L8: 56 | M8: 57.26 | N8: 57.55 | O8: 59.1 | P8: 59.91
A9: FPT | B9: Part des femmes bénéficiaires (en %) | C9: 48.4 | D9: 49.8 | E9: 51.2 | F9: 52.2 | G9: 54.3 | H9: 55.67 | I9: 56.69 | J9: 58.05 | K9: 59.4 | L9: 61 | M9: 61.82 | N9: 62.66 | O9: 63.7 | P9: 64.52
A10: Hôpitaux | B10: Part des femmes bénéficiaires (en %) | C10: 75.6 | D10: 74.4 | E10: 75 | F10: 75.9 | G10: 76.5 | H10: 77.19 | I10: 78.43 | J10: 79 | K10: 80 | L10: 81 | M10: 81.56 | N10: 82.12 | O10: 82.4 | P10: 83.02
A11: Autres | B11: Part des femmes bénéficiaires (en %) | C11: 72.5 | D11: 69.7 | E11: 70.6 | F11: 72.3 | G11: 74.1 | H11: 75.29 | I11: 73.32 | J11: 75.6 | K11: 76.3 | L11: 77 | M11: 77.52 | N11: 77.92 | O11: 79 | P11: 79.01
A12: FPH | B12: Part des femmes bénéficiaires (en %) | C12: 72.9 | D12: 74 | E12: 75.5 | F12: 75.5 | G12: 76.2 | H12: 76.97 | I12: 77.8 | J12: 78.61 | K12: 79.6 | L12: 81 | M12: 81.06 | N12: 81.61 | O12: 82 | P12: 82.55
A13: Ensemble fonction publique | B13: Part des femmes bénéficiaires (en %) | C13: 54.2 | D13: 56 | E13: 57.3 | F13: 58.5 | G13: 60.4 | H13: 61.97 | I13: 62.94 | J13: 63.8 | K13: 64.6 | L13: 66 | M13: 67.1 | N13: 68.11 | O13: 69.1 | P13: 70.02
A14: Source : Fonds pour l'insertion des personnes handicapées dans la fonction publique (FIPHFP),
A15: Champ : Employeurs publics d’au moins 20 agents à temps plein ou leur équivalent, hors aides-soignants, infirmiers et emplois particuliers (stagiaires handicapés accueillis pour des stages pratiques)
A16: Lecture : En 2024, dans l'ensemble de la fonction publique, 70% des bénéficiaires de l'obligation d'emploi en faveur des travailleurs handicapés sont des femmes.
A17: (1) Depuis 2014, les universités qui étaient auparavant rattachées au ministère de l'Éducation nationale sont comptabilisées parmi les établissements publics.

Sheet Figure 7
A1: Bénéficiaires de l'obligation d'emploi en faveur des travailleurs handicapés par ministères au 31 décembre 2024
B3: Au 31 décembre 2024 | F3: Au 31 décembre 2023 | J3: Évolution 2024/2023
B4: Effectif total rémunéré (en milliers) | C4: Nombre de bénéficiaires (en milliers) | D4: Taux d'emploi direct (en %) | E4: Part des femmes parmis les bénéficiaires (en %) | F4: Effectif total rémunéré (en milliers) | G4: Nombre de bénéficiaires (en milliers) | H4: Taux d'emploi direct (en %) | I4: Part des femmes parmis les bénéficiaires (en %) | J4: Effectif total rémunéré (en %) | K4: Nombre de bénéficiaires (en %) | L4: Taux d'emploi direct (en points de %) | M4: Part des femmes parmis les bénéficiaires (en points de %)
A5: Ensemble ministères | B5: 1589.684 | C5: 80.003 | D5: 5 | E5: 69.6 | F5: 1642.462 | G5: 75.79 | H5: 4.6144142 | I5: 67.95 | J5: =(B5-F5)/F5*100 -> -3.2133468 | K5: =(C5-G5)/G5*100 -> 5.5587808 | L5: =D5-H5 -> 0.38558579 | M5: =E5-I5 -> 1.65
A6: Dont…
A7: Europe et Affaires étrangères | B7: 7.696 | C7: 0.452 | D7: 5.9 | E7: 48.5 | F7: 7.451 | G7: 0.435 | H7: 5.8381425 | I7: 44.83 | J7: =(B7-F7)/F7*100 -> 3.2881492 | K7: =(C7-G7)/G7*100 -> 3.908046 | L7: =D7-H7 -> 0.061857469 | M7: =E7-I7 -> 3.67
A8: Agriculture et Alimentation | B8: 29.23 | C8: 1.566 | D8: 5.4 | E8: 64 | F8: 28.527 | G8: 1.416 | H8: 4.9637186 | I8: 62.99 | J8: =(B8-F8)/F8*100 -> 2.464332 | K8: =(C8-G8)/G8*100 -> 10.59322 | L8: =D8-H8 -> 0.43628142 | M8: =E8-I8 -> 1.01
A9: Économie et Finances, Action et Comptes publics | B9: 126.458 | C9: 8.26 | D9: 6.5 | E9: 58.7 | F9: 125.977 | G9: 8.935 | H9: 7.0925645 | I9: 56.61 | J9: =(B9-F9)/F9*100 -> 0.38181573 | K9: =(C9-G9)/G9*100 -> -7.5545607 | L9: =D9-H9 -> -0.59256452 | M9: =E9-I9 -> 2.09
A10: Culture | B10: 9.237 | C10: 0.486 | D10: 5.3 | E10: 66.5 | F10: 9.204 | G10: 0.461 | H10: 5.0086919 | I10: 65.29 | J10: =(B10-F10)/F10*100 -> 0.35853977 | K10: =(C10-G10)/G10*100 -> 5.4229935 | L10: =D10-H10 -> 0.29130813 | M10: =E10-I10 -> 1.21
A11: Armées | B11: 58.82 | C11: 4.354 | D11: 7.4 | E11: 44.3 | F11: 57.563 | G11: 4.055 | H11: 7.0444556 | I11: 43.8 | J11: =(B11-F11)/F11*100 -> 2.1836944 | K11: =(C11-G11)/G11*100 -> 7.3736128 | L11: =D11-H11 -> 0.35554436 | M11: =E11-I11 -> 0.5
A12: Transition écologique et solidaire | B12: 44.124 | C12: 3.146 | D12: 7.1 | E12: 42.1 | F12: 43.897 | G12: 3.011 | H12: 6.8592387 | I12: 39.61 | J12: =(B12-F12)/F12*100 -> 0.51711962 | K12: =(C12-G12)/G12*100 -> 4.4835603 | L12: =D12-H12 -> 0.24076133 | M12: =E12-I12 -> 2.49
A13: Hors aviation civile | B13: 33.722 | C13: 2.552 | D13: 7.6 | E13: 45.1 | F13: 33.504 | G13: 2.436 | H13: 7.2707736 | I13: 42.49 | J13: =(B13-F13)/F13*100 -> 0.65066858 | K13: =(C13-G13)/G13*100 -> 4.7619048 | L13: =D13-H13 -> 0.32922636 | M13: =E13-I13 -> 2.61
A14: Dont aviation civile | B14: 10.402 | C14: 0.594 | D14: 5.7 | E14: 29 | F14: 10.393 | G14: 0.571 | H14: 5.53257 | I14: 27.32 | J14: =(B14-F14)/F14*100 -> 0.086596748 | K14: =(C14-G14)/G14*100 -> 4.028021 | L14: =D14-H14 -> 0.16743 | M14: =E14-I14 -> 1.68
A15: Éducation nationale, Enseignement supérieur, Recherche et Innovation | B15: 1011.694 | C15: 47.499 | D15: 4.7 | E15: 80.2 | F15: 1069.088 | G15: 43.73 | H15: 4.0904023 | I15: 79.13 | J15: =(B15-F15)/F15*100 -> -5.368501 | K15: =(C15-G15)/G15*100 -> 8.6187972 | L15: =D15-H15 -> 0.60959771 | M15: =E15-I15 -> 1.07
A16: Intérieur, Cohésion des territoires et Outre-Mer | B16: 196.308 | C16: 7.54 | D16: 3.8 | E16: 47.5 | F16: 196.276 | G16: 7.373 | H16: 3.756445 | I16: 48.43 | J16: =(B16-F16)/F16*100 -> 0.016303573 | K16: =(C16-G16)/G16*100 -> 2.265021 | L16: =D16-H16 -> 0.043554994 | M16: =E16-I16 -> -0.93
A17: Justice | B17: 90.497 | C17: 5.66 | D17: 6.3 | E17: 63.6 | F17: 88.728 | G17: 5.456 | H17: 6.1491299 | I17: 59.77 | J17: =(B17-F17)/F17*100 -> 1.9937337 | K17: =(C17-G17)/G17*100 -> 3.7390029 | L17: =D17-H17 -> 0.15087007 | M17: =E17-I17 -> 3.83
A18: Ministères sociaux | B18: 12.355 | C18: 0.896 | D18: 7.3 | E18: 74.6 | F18: 12.475 | G18: 0.779 | H18: 6.244489 | I18: 73.68 | J18: =(B18-F18)/F18*100 -> -0.96192385 | K18: =(C18-G18)/G18*100 -> 15.019255 | L18: =D18-H18 -> 1.055511 | M18: =E18-I18 -> 0.92
A19: Services du Premier ministre | B19: 2.884 | C19: 0.133 | D19: 4.6 | E19: 45.9 | F19: 2.906 | G19: 0.128 | H19: 4.40468 | I19: 50.78 | J19: =(B19-F19)/F19*100 -> -0.75705437 | K19: =(C19-G19)/G19*100 -> 3.90625 | L19: =D19-H19 -> 0.19532003 | M19: =E19-I19 -> -4.88
A20: Source : Fonds pour l'insertion des personnes handicapées dans la fonction publique (FIPHFP).
A21: Champ : Ministères, employeurs publics d’au moins 20 agents à temps plein ou leur équivalent, hors aides-soignants, infirmiers et emplois particuliers (stagiaires handicapés accueillis pour des stages pratiques).
A22: Lecture : Au 31 décembre 2024, le taux d'emploi direct au ministère de la culture était de 5,3 %, soit une hausse de 0,3 point par rapport à 2023.
A23: Note 1 : Le taux d’emploi direct est le rapport entre le nombre de bénéficiaires de l’obligation d’emploi et l’effectif total rémunéré.
A24: Note 2 : Ces données sont celles déclarées par les employeurs. Le nombre de déclarants évoluant chaque année, cela peut entraîner des évolutions du nombre de bénéficiaires de l'obligation d'emploi plus ou moins importantes d'une année sur l'autre.
A25: Note 3 : L'appellation des ministères renvoie à la nomenclature d'exécution de la loi de finances initiale de l'année, à l'exception des ministères économiques et financiers, ceux de l'enseignement, de l'Intérieur et de l'Outre-Mer ainsi que les ministères sociaux qui sont issus de regroupements.

Sheet Figure 8
A1: Répartition des bénéficiaires de l'obligation d'emploi en faveur des travailleurs handicapés par statut et par sexe dans les trois versants de la fonction publique au 31 décembre 2024
A2: en %
B3: Fonctionnaires | E3: Contractuels | F3: Emplois particuliers | G3: Ouvriers d'État | H3: Total
B4: Catégorie A | C4: Catégorie B | D4: Catégorie C
A5: Ministères | B5: 51.9 | C5: 20 | D5: 18 | E5: 9.4 | F5: 0.2 | G5: 0.5 | H5: 100
A6: EPA | B6: 30.6 | C6: 32.2 | D6: 16.8 | E6: 18.3 | F6: 0.9 | G6: 1.2 | H6: 100
A7: Ensemble FPE | B7: 46.3 | C7: 23.2 | D7: 17.7 | E7: 11.7 | F7: 0.4 | G7: 0.7 | H7: 100
A8: Ensemble FPE (hors enseignement) | B8: 22.7 | C8: 38.1 | D8: 26.5 | E8: 10.7 | F8: 0.7 | G8: 1.3 | H8: 100
A9: Collectivités territoriales | B9: 6.5 | C9: 9.5 | D9: 74.4 | E9: 8.6 | F9: 1 | G9: 0 | H9: 100
A10: EPA locaux | B10: 6.9 | C10: 12.9 | D10: 67.4 | E10: 11.7 | F10: 1 | G10: 0 | H10: 100
A11: Ensemble FPT | B11: 6.6 | C11: 10.4 | D11: 72.6 | E11: 9.4 | F11: 1 | G11: 0 | H11: 100
A12: Hôpitaux | B12: 21.2 | C12: 37 | D12: 33.7 | E12: 8 | F12: 0.2 | G12: 0 | H12: 100
A13: Autres | B13: 9 | C13: 28.9 | D13: 38.6 | E13: 22.3 | F13: 1.2 | G13: 0 | H13: 100
A14: Ensemble FPH | B14: 19.8 | C14: 36 | D14: 34.3 | E14: 9.7 | F14: 0.3 | G14: 0 | H14: 100
A15: Ensemble de la fonction publique | B15: 23.4 | C15: 20.3 | D15: 45.2 | E15: 10.3 | F15: 0.6 | G15: 0.2 | H15: 100
A16: Source : Fonds pour l'insertion des personnes handicapées dans la fonction publique (FIPHFP).
A17: Champ : Employeurs publics d’au moins 20 agents à temps plein ou leur équivalent, hors aides-soignants, infirmiers et emplois particuliers (stagiaires handicapés accueillis pour des stages pratiques).
A18: Lecture : Au 31 décembre 2024, parmis les bénéficiaires de l'obligation d'emploi en faveur des travailleurs handicapés de la FPE, 69 % étaient des femmes.
A110: Tableau 32 : Répartition des bénéficiaires par catégorie hiérarchique et par sexe
B112: Titulaires Catégorie A | D112: Titulaires Catégorie B | F112: Titulaires Catégorie C | H112: Ouvriers dEtat
B113: Féminin | C113: Masculin | D113: Féminin | E113: Masculin | F113: Féminin | G113: Masculin | H113: Féminin
A115: COMMISSION NATIONALE INFORMATIQUE ET DES LIBERTES | D115: 1
A116: DIRECTION GENERALE DE L AVIATION CIVILE | B116: 26 | C116: 79 | D116: 59 | E116: 296 | F116: 53 | G116: 30 | H116: 1
A117: API AUTORITE DE REGULATION DES ACTIVITES FERROVIAIRES
A118: LYCEE CHARLES ET ADRIEN DUPUY
A119: MINISTERE DE L AGRICULTURE ET DE L ALIMENTATION | B119: 270 | C119: 230 | D119: 296 | E119: 203 | F119: 172 | G119: 46
A120: MINISTERE DE L ECONOMIE DES FINANCES ET DE LA RELANCE | B120: 869 | C120: 886 | D120: 1762 | E120: 1862 | F120: 2148 | G120: 1798
A121: MINISTERE DE L EDUCATION NATIONALE JEUNESSE SPORTS | B121: 20732 | C121: 6097 | D121: 1190 | E121: 451 | F121: 2231 | G121: 667
A122: MINISTERE DE L INTERIEUR | B122: 143 | C122: 119 | D122: 958 | E122: 2757 | F122: 1815 | G122: 818 | H122: 5
A123: MINISTERE DE LA CULTURE | B123: 53 | C123: 26 | D123: 81 | E123: 56 | F123: 113 | G123: 89
A124: MINISTERE DE LA JUSTICE | B124: 493 | C124: 283 | D124: 831 | E124: 313 | F124: 1393 | G124: 1461
A125: MINISTERE DES AFFAIRES ETRANGERES ET EUROPEENNES | B125: 43 | C125: 27 | D125: 64 | E125: 38 | F125: 112 | G125: 63
A126: MINISTERE DES ARMEES | B126: 77 | C126: 140 | D126: 277 | E126: 707 | F126: 1117 | G126: 1043 | H126: 79
A127: MINISTERE DU TRAVAIL DES RELATIONS SOCIALES DE LA FAMILLE ET DE LA SOLIDARITE | B127: 158 | C127: 59 | D127: 205 | E127: 63 | F127: 302 | G127: 102
A128: MINISTERE GOUVERNEMENT PREMIER MINISTRE | B128: 7 | C128: 12 | D128: 14 | E128: 5 | F128: 21 | G128: 20
A129: MINISTERE TRANSITION ECOLOGIQUE | B129: 104 | C129: 124 | D129: 400 | E129: 566 | F129: 506 | G129: 957 | H129: 2
A130: Ministère | B130: 22975 | C130: 8082 | D130: 6138 | E130: 7317 | F130: 9983 | G130: 7094 | H130: 87
A131: CAISSE DES DEPOTS ET CONSIGNATIONS | B131: 25 | C131: 21 | D131: 83 | E131: 39 | F131: 81 | G131: 25
A132: CAISSE NATIONALE MILITAIRE DE SECURITE SOCIALE | B132: 1 | C132: 1 | D132: 24 | E132: 23 | F132: 43 | G132: 31
A133: CENTRE NATIONAL DE RECHERCHE SCIENTIFIQUE PARIS | B133: 441 | C133: 470 | D133: 223 | E133: 104 | F133: 22 | G133: 19
...

Sheet Figure 9
A1: Bénéficiaires de l'obligation d'emploi en faveur des travailleurs handicapés occupant un emploi particulier(1) par sexe et par versant de la fonction publique
A2: en milliers
C3: 2014 | D3: 2015 | E3: 2016 | F3: 2017 | G3: 2018 | H3: 2019 | I3: 2020 | J3: 2021 | K3: 2022 | L3: 2023 | M3: 2024
A4: Ensemble fonction publique | B4: Hommes | C4: 1.8 | D4: 2.2 | E4: 2.2 | F4: 2.3 | G4: 1.8 | H4: 1.4 | I4: 1 | J4: 1 | K4: 0.9 | L4: 0.8 | M4: 0.886
B5: Femmes | C5: 1.7 | D5: 2.2 | E5: 2.3 | F5: 2.6 | G5: 2 | H5: 1.4 | I5: 1.2 | J5: 1.2 | K5: 1 | L5: 1 | M5: 1.09
B6: Ensemble | C6: 3.5 | D6: 4.4 | E6: 4.5 | F6: 4.9 | G6: 3.9 | H6: 2.8 | I6: 2.2 | J6: 2.3 | K6: 2 | L6: 1.9 | M6: 1.976
A7: dont Fonction publique territoriale | B7: Hommes | C7: 1.4 | D7: 1.7 | E7: 1.8 | F7: 1.9 | G7: 1.5 | H7: 1.1 | I7: 0.8 | J7: 0.9 | K7: 0.8 | L7: 0.7 | M7: 0.665
B8: Femmes | C8: 0.9 | D8: 1.3 | E8: 1.3 | F8: 1.4 | G8: 1.2 | H8: 1 | I8: 0.8 | J8: 0.8 | K8: 0.7 | L8: 0.7 | M8: 0.71
B9: Ensemble | C9: 2.3 | D9: 3 | E9: 3.1 | F9: 3.3 | G9: 2.7 | H9: 2.1 | I9: 1.6 | J9: 1.7 | K9: 1.5 | L9: 1.3 | M9: 1.375
A10: Source : Fonds pour l'insertion des personnes handicapées dans la fonction publique (FIPHFP).
A11: Champ : Employeurs publics d’au moins 20 agents à temps plein ou leur équivalent, hors aides-soignants, infirmiers et emplois particuliers.
A12: Lecture : En 2024, 900 hommes bénéficiaires de l'obligation d'emploi en faveur des travailleurs handicapés occupaient un emploi particulier dans la fonction publique.
A13: Note : Ces données sont celles déclarées par les employeurs. Le nombre de déclarants évoluant chaque année, cela peut entraîner des évolutions du nombre de bénéficiaires de l'obligation d'emploi plus ou moins importantes d'une année sur l'autre.
A14: (1) Stagiaires handicapés accueillis pour des stages pratiques dans le cadre de formations diplômantes ou de conventions conclues avec des structures de travail protégées, apprentis, CES, CEC, CAE, CA, emplois jeunes, emplois Berkani de droit privé.
