Workbook

Sheet Lisez-moi
A1: Modèle financier du catalogue de réformes — version tableur (30 octobre 2026)
A3: Les cellules jaunes sont des hypothèses modifiables (feuilles Hypothèses, Viviers, Réformes). Tout le reste est calculé.
A4: Le classeur calcule un régime permanent simplifié à l'horizon choisi : il ne simule pas les cohortes année par année.
A5: Le moteur de référence est modele/modele.py ; la feuille Synthèse compare les deux calculs et affiche leur écart.
A6: Convention : économies = écart à une référence qui remplace tous les départs, en M€ 2026 constants.
A7: Ordre d'application : dans chaque vivier, chaque réforme porte sur le reliquat laissé par les précédentes (lignes triées par vivier puis ordre).
A8: Capacité : le non-remplacement ne peut dépasser les départs mobilisables du vivier, B × (1 − (1 − r × multiplicateur)^horizon).
A9: Coût d'un poste non remplacé : MIN(coût moyen ; coût d'entrée × (1 + GVT)^(horizon / 2)) × multiplicateur de coût.
A10: Sources et justification de chaque paramètre : recherche/11_catalogue_reformes.md et recherche/12_scenarios_seuils.md.

Sheet Synthese
A1: Indicateur | B1: Prudent | C1: Intermédiaire | D1: Ambitieux | E1: Radical
A2: Postes en moins à l'horizon — tableur (régime permanent) | B2: =Calcul_prudent!$L$32 | C2: =Calcul_intermediaire!$L$32 | D2: =Calcul_ambitieux!$L$32 | E2: =Calcul_radical!$L$32
A3: Postes en moins en 2036 — moteur | B3: 11106.4 | C3: 56141.6 | D3: 120249.7 | E3: 194475.8
A4: Économie nette annuelle à l'horizon (M€) — tableur | B4: =Calcul_prudent!$S$32 | C4: =Calcul_intermediaire!$S$32 | D4: =Calcul_ambitieux!$S$32 | E4: =Calcul_radical!$S$32
A5: Économie nette 2036 (M€) — moteur | B5: 617.9 | C5: 2517.1 | D5: 5280.1 | E5: 8429.7
A6: Économie consolidée APU à l'horizon (M€) — tableur | B6: =Calcul_prudent!$T$32 | C6: =Calcul_intermediaire!$T$32 | D6: =Calcul_ambitieux!$T$32 | E6: =Calcul_radical!$T$32
A7: Économie consolidée APU 2036 (M€) — moteur | B7: 458 | C7: 1710 | D7: 3538.7 | E7: 5725.7
A8: Investissements (M€) — tableur | B8: =Calcul_prudent!$U$32 | C8: =Calcul_intermediaire!$U$32 | D8: =Calcul_ambitieux!$U$32 | E8: =Calcul_radical!$U$32
A9: Cumul net 2027-2036 (M€) — moteur | B9: 3464.1 | C9: 12626.6 | D9: 25701.1 | E9: 35448.4
A10: Écart tableur / moteur sur les postes (%) | B10: =IF(B3=0,0,(B2-B3)/B3) | C10: =IF(C3=0,0,(C2-C3)/C3) | D10: =IF(D3=0,0,(D2-D3)/D3) | E10: =IF(E3=0,0,(E2-E3)/E3)
A11: Le tableur est un régime permanent sans calendrier : un petit écart avec le moteur (cohortes, montée en charge, mi-année) est attendu.
A13: Test des seuils (recalculé avec les hypothèses du classeur)
A14: Seuil (postes) | B14: Atteint en intermédiaire ? | C14: Atteint en radical ? | D14: Capacité de départs sur l'horizon | E14: Total des viviers | F14: Verdict tableur | G14: Verdict de la note 12 (hypothèses centrales)
A15: 50000 | B15: =IF(Calcul_intermediaire!$L$32>=A15,"oui","non") | C15: =IF(Calcul_radical!$L$32>=A15,"oui","non") | D15: =Viviers!I10 | E15: =Viviers!C10 | F15: =IF(B15="oui","conditionnel",IF(C15="oui","conditionnel",IF(D15>=A15,"non démontré","incompatible"))) | G15: conditionnel
A16: 100000 | B16: =IF(Calcul_intermediaire!$L$32>=A16,"oui","non") | C16: =IF(Calcul_radical!$L$32>=A16,"oui","non") | D16: =Viviers!I10 | E16: =Viviers!C10 | F16: =IF(B16="oui","conditionnel",IF(C16="oui","conditionnel",IF(D16>=A16,"non démontré","incompatible"))) | G16: conditionnel
A17: 200000 | B17: =IF(Calcul_intermediaire!$L$32>=A17,"oui","non") | C17: =IF(Calcul_radical!$L$32>=A17,"oui","non") | D17: =Viviers!I10 | E17: =Viviers!C10 | F17: =IF(B17="oui","conditionnel",IF(C17="oui","conditionnel",IF(D17>=A17,"non démontré","incompatible"))) | G17: non démontré
A18: 500000 | B18: =IF(Calcul_intermediaire!$L$32>=A18,"oui","non") | C18: =IF(Calcul_radical!$L$32>=A18,"oui","non") | D18: =Viviers!I10 | E18: =Viviers!C10 | F18: =IF(B18="oui","conditionnel",IF(C18="oui","conditionnel",IF(D18>=A18,"non démontré","incompatible"))) | G18: incompatible
A19: 800000 | B19: =IF(Calcul_intermediaire!$L$32>=A19,"oui","non") | C19: =IF(Calcul_radical!$L$32>=A19,"oui","non") | D19: =Viviers!I10 | E19: =Viviers!C10 | F19: =IF(B19="oui","conditionnel",IF(C19="oui","conditionnel",IF(D19>=A19,"non démontré","incompatible"))) | G19: incompatible
A20: 1000000 | B20: =IF(Calcul_intermediaire!$L$32>=A20,"oui","non") | C20: =IF(Calcul_radical!$L$32>=A20,"oui","non") | D20: =Viviers!I10 | E20: =Viviers!C10 | F20: =IF(B20="oui","conditionnel",IF(C20="oui","conditionnel",IF(D20>=A20,"non démontré","incompatible"))) | G20: incompatible
A21: 1500000 | B21: =IF(Calcul_intermediaire!$L$32>=A21,"oui","non") | C21: =IF(Calcul_radical!$L$32>=A21,"oui","non") | D21: =Viviers!I10 | E21: =Viviers!C10 | F21: =IF(B21="oui","conditionnel",IF(C21="oui","conditionnel",IF(D21>=A21,"non démontré","incompatible"))) | G21: incompatible

Sheet Hypotheses
A1: Paramètre | B1: Valeur | C1: Source / justification
A2: Horizon (années) | B2: 10 | C2: 2027-2036, comme le moteur
A3: GVT individuel réel | B3: 0.01 | C3: [HYPOTHÈSE] Taux individuel réel national NON TROUVÉ (01c). 1 %/an, plafonné au coût moyen ; sensibilité 0-2 % en phase 5.
A4: Conservation APU (lecture consolidée) | B4: 0.65 | C4: [ESTIMATION] Part du coût hors pension conservée en lecture APU statique. Charges employeur hors pension : 13,7 à 17,6 % du coût d'entrée (PAP 156 : coût HCAS moins rémunération d'activité). Retenue pension 11,1 % (01c) et CSG-CRDS sur la rémunération reviennent aussi aux APU : environ 32 % au total, IR non chiffré. Retenu : 1 - 0,35.
A5: Multiplicateur des taux de réduction | B5: 1 | C5: 1 = catalogue ; sensibilité testée 0,5-1,5
A6: Multiplicateur des départs mobilisables | B6: 1 | C6: 1 = retraites ; 1,605 = toutes sorties de fonctionnaires
A7: Multiplicateur des coûts par ETP | B7: 1 | C7: sensibilité testée 0,8-1,2
A8: Multiplicateur des investissements | B8: 1 | C8: sensibilité testée 0,5-2
A10: Versant | B10: Coût d'entrée hors pension (k€) | C10: Coût moyen hors pension (k€) | D10: Source
A11: FPE | B11: 44.05 | C11: 48.99 | D11: [ESTIMATION] Moyenne des coûts HCAS d'entrée et globaux des PAP 2026 des programmes 156 et 218 par catégorie A/B/C, pondérée par les corps administratifs et techniques de la FPE fin 2024 (A 79 668, B 157 099, C 142 142). data/france/01c_couts_documentes.csv, data/france/02_metiers.csv.
A12: FPE_DGFIP | B12: 40.55 | C12: 45.41 | D12: [ESTIMATION] Coûts HCAS du seul PAP 2026 du programme 156 (DGFiP), même pondération A/B/C.
A13: FPT | B13: 33.67 | C13: 37.45 | D13: [HYPOTHÈSE] Coûts FPE multipliés par le rapport des salaires bruts moyens par EQTP FPT/FPE 2024 (2 857,75 / 3 738,28 = 0,7645). Aucun coût d'entrée territorial publié n'a été trouvé.
A14: FPH | B14: 33.67 | C14: 37.45 | D14: [HYPOTHÈSE] Même proxy que la FPT : le salaire moyen FPH inclut les médecins et surestimerait le coût des administratifs hospitaliers.
A15: HORS_FP | B15: 44.05 | C15: 48.99 | D15: [HYPOTHÈSE] Organismes de protection sociale et France Travail, agents de droit privé : aucun coût d'entrée publié trouvé ; proxy FPE. Confiance faible.

Sheet Viviers
A1: vivier_id | B1: versant | C1: etp_base | D1: taux_departs_annuel | E1: plafond_reduction_prudent | F1: plafond_reduction_intermediaire | G1: plafond_reduction_ambitieux | H1: plafond_reduction_radical | I1: Capacité de départs sur l'horizon (ETP) | J1: description | K1: sources
A2: V_DGFIP | B2: FPE_DGFIP | C2: 94467.5 | D2: 0.026067 | E2: 0.05 | F2: 0.12 | G2: 0.2 | H2: 0.35 | I2: =C2*(1-(1-MIN(1,D2*Hypotheses!$B$6))^Hypotheses!$B$2) | J2: DGFiP, titulaires et contractuels en fonction 2025 | K2: DGFiP cahier statistique 2025 PDF p.46-47 (88 659 + 5 910 PP) ; conversion EQTP/PP FPE 2024 (IP2094 / DGAFP) ; départs : pensions civiles FPE 2025 / fonctionnaires FPE
A3: V_FPE_AUTRES | B3: FPE | C3: 231659.2 | D3: 0.026067 | E3: 0.05 | F3: 0.12 | G3: 0.2 | H3: 0.35 | I3: =C3*(1-(1-MIN(1,D3*Hypotheses!$B$6))^Hypotheses!$B$2) | J3: Autres corps administratifs et techniques de la FPE (ministères et EPA, dont opérateurs) | K3: DGAFP RA 2026 postes FPE figure 2 B11+B26+B37 (79 668 + 157 099 + 142 142) moins DGFiP et filière administrative scolaire
A4: V_MEN_ADM | B4: FPE | C4: 50849 | D4: 0.026067 | E4: 0.05 | F4: 0.12 | G4: 0.2 | H4: 0.35 | I4: =C4*(1-(1-MIN(1,D4*Hypotheses!$B$6))^Hypotheses!$B$2) | J4: Filière administrative de l'Éducation nationale | K4: DEPP, personnels non enseignants, tableau 3.1 L27 (ETP au 30/11/2025)
A5: V_FPT_ADM | B5: FPT | C5: 444816.9 | D5: 0.033094 | E5: 0.05 | F5: 0.12 | G5: 0.2 | H5: 0.35 | I5: =C5*(1-(1-MIN(1,D5*Hypotheses!$B$6))^Hypotheses!$B$2) | J5: Filière administrative de la fonction publique territoriale | K5: DGAFP RA 2026 postes FPT figure 1 filière S28 ; conversion EQTP/PP FPT 2024 ; départs : pensions CNRACL FPT 2025 / fonctionnaires FPT
A6: V_FPH_ADM | B6: FPH | C6: 119263.7 | D6: 0.027512 | E6: 0.05 | F6: 0.12 | G6: 0.2 | H6: 0.35 | I6: =C6*(1-(1-MIN(1,D6*Hypotheses!$B$6))^Hypotheses!$B$2) | J6: Filière administrative de la fonction publique hospitalière | K6: DGAFP RA 2026 postes FPH figure 1 filière T25 ; conversion EQTP/PP FPH 2024 ; départs : pensions CNRACL FPH 2025 / fonctionnaires FPH
A7: V_OPS | B7: HORS_FP | C7: 162623 | D7: 0.026067 | E7: 0.05 | F7: 0.12 | G7: 0.2 | H7: 0.35 | I7: =C7*(1-(1-MIN(1,D7*Hypotheses!$B$6))^Hypotheses!$B$2) | J7: Organismes de protection sociale (droit privé, financement public prédominant) | K7: DGAFP RA 2026 effectifs, figure 3 (162 623 PP fin 2024), utilisées comme majorant des ETP ; taux de départ FPE faute de donnée propre
A8: V_FT | B8: HORS_FP | C8: 48232 | D8: 0.026067 | E8: 0.05 | F8: 0.12 | G8: 0.2 | H8: 0.35 | I8: =C8*(1-(1-MIN(1,D8*Hypotheses!$B$6))^Hypotheses!$B$2) | J8: France Travail | K8: Jaune Opérateurs PLF 2027, plafond d'emplois 2027 (48 232 ETPT) ; taux de départ FPE faute de donnée propre
A9: V_FONCT | B9: FPE | C9: 0 | D9: 0 | E9: 0.05 | F9: 0.12 | G9: 0.2 | H9: 0.35 | I9: =C9*(1-(1-MIN(1,D9*Hypotheses!$B$6))^Hypotheses!$B$2) | J9: Dépenses de fonctionnement sans effectif (achats, immobilier, instances) | K9: Sans effectif : les fiches y portent des économies de fonctionnement en M€
A10: Total | C10: =SUM(C2:C9) | I10: =SUM(I2:I9)

Sheet Reformes
A1: id | B1: intitule | C1: vivier_id | D1: ordre | E1: part_non_remplacement | F1: part_redeploiement | G1: cout_recurrent_proportionnel | H1: taux_prudent | I1: taux_intermediaire | J1: taux_ambitieux | K1: taux_radical | L1: invest_meur_prudent | M1: invest_meur_intermediaire | N1: invest_meur_ambitieux | O1: invest_meur_radical | P1: cout_recurrent_meur_prudent | Q1: cout_recurrent_meur_intermediaire | R1: cout_recurrent_meur_ambitieux | S1: cout_recurrent_meur_radical | T1: eco_fonct_meur_prudent | U1: eco_fonct_meur_intermediaire | V1: eco_fonct_meur_ambitieux | W1: eco_fonct_meur_radical | X1: effet_recettes_meur_prudent | Y1: effet_recettes_meur_intermediaire | Z1: effet_recettes_meur_ambitieux | AA1: effet_recettes_meur_radical | AB1: confiance | AC1: fiche
A2: R01 | B2: Automatiser les contrôles de forme et supprimer les ressaisies fiscales | C2: V_DGFIP | D2: 20 | E2: 1 | F2: 0 | G2: 0 | H2: 0.0055 | I2: 0.011 | J2: 0.022 | K2: 0.033 | L2: 42.137 | M2: 84.274 | N2: 168.549 | O2: 252.823 | P2: 0 | Q2: 0 | R2: 0 | S2: 0 | T2: 0 | U2: 0 | V2: 0 | W2: 0 | X2: 0 | Y2: 0 | Z2: 0 | AA2: 0 | AB2: moyen | AC2: recherche/fiches/R01_automatiser_les_controles_de_forme_et_supprimer_.md
A3: R02 | B3: Mutualiser les fonctions RH et informatiques de la DGFiP | C3: V_DGFIP | D3: 30 | E3: 1 | F3: 0 | G3: 0 | H3: 0.001 | I3: 0.0047 | J3: 0.007 | K3: 0.0094 | L3: 7.619 | M3: 35.612 | N3: 52.449 | O3: 69.64 | P3: 0 | Q3: 0 | R3: 0 | S3: 0 | T3: 0 | U3: 0 | V3: 0 | W3: 0 | X3: 0 | Y3: 0 | Z3: 0 | AA3: 0 | AB3: faible | AC3: recherche/fiches/R02_mutualiser_les_fonctions_rh_et_informatiques_de_.md
A4: R03 | B4: Utiliser l'IA pour cibler le contrôle fiscal, à effectifs redéployés | C4: V_DGFIP | D4: 40 | E4: 0 | F4: 1 | G4: 0 | H4: 0 | I4: 0.01 | J4: 0.02 | K4: 0.03 | L4: 0 | M4: 25.223 | N4: 25.223 | O4: 25.223 | P4: 0 | Q4: 0.992 | R4: 0.992 | S4: 0.992 | T4: 0 | U4: 0 | V4: 0 | W4: 0 | X4: 0 | Y4: 0 | Z4: 0 | AA4: 0 | AB4: faible | AC4: recherche/fiches/R03_utiliser_l_ia_pour_cibler_le_controle_fiscal_a_e.md
A5: R28 | B5: Professionnaliser et mutualiser davantage les achats publics | C5: V_FONCT | D5: 10 | E5: 1 | F5: 0 | G5: 0 | H5: 0 | I5: 0 | J5: 0 | K5: 0 | L5: 0 | M5: 0 | N5: 0 | O5: 0 | P5: 0 | Q5: 0 | R5: 0 | S5: 0 | T5: 61 | U5: 122 | V5: 244 | W5: 365 | X5: 0 | Y5: 0 | Z5: 0 | AA5: 0 | AB5: moyen | AC5: recherche/fiches/R28_professionnaliser_et_mutualiser_davantage_les_ac.md
A6: R29 | B6: Réduire les surfaces de bureaux au-delà de la foncière de l'État | C6: V_FONCT | D6: 11 | E6: 1 | F6: 0 | G6: 0 | H6: 0 | I6: 0 | J6: 0 | K6: 0 | L6: 0 | M6: 0 | N6: 0 | O6: 0 | P6: 0 | Q6: 0 | R6: 0 | S6: 0 | T6: 0 | U6: 0 | V6: 100 | W6: 250 | X6: 0 | Y6: 0 | Z6: 0 | AA6: 0 | AB6: faible | AC6: recherche/fiches/R29_reduire_les_surfaces_de_bureaux_au_dela_de_la_fo.md
A7: R30 | B7: Réexaminer périodiquement les commissions et instances consultatives | C7: V_FONCT | D7: 12 | E7: 1 | F7: 0 | G7: 0 | H7: 0 | I7: 0 | J7: 0 | K7: 0 | L7: 0 | M7: 0 | N7: 0 | O7: 0 | P7: 0 | Q7: 0 | R7: 0 | S7: 0 | T7: 0 | U7: 0 | V7: 0 | W7: 0 | X7: 0 | Y7: 0 | Z7: 0 | AA7: 0 | AB7: faible | AC7: recherche/fiches/R30_reexaminer_periodiquement_les_commissions_et_ins.md
A8: R04 | B8: Revoir les missions des opérateurs et regrouper ceux qui se recouvrent | C8: V_FPE_AUTRES | D8: 10 | E8: 0.8 | F8: 0.2 | G8: 0 | H8: 0.005 | I8: 0.015 | J8: 0.03 | K8: 0.06 | L8: 81.637 | M8: 244.91 | N8: 489.82 | O8: 979.64 | P8: 0 | Q8: 0 | R8: 0 | S8: 0 | T8: 0 | U8: 0 | V8: 0 | W8: 0 | X8: 0 | Y8: 0 | Z8: 0 | AA8: 0 | AB8: moyen | AC8: recherche/fiches/R04_revoir_les_missions_des_operateurs_et_regrouper_.md
A9: R05 | B9: Allouer les effectifs de l'État territorial selon des besoins mesurés | C9: V_FPE_AUTRES | D9: 11 | E9: 1 | F9: 0 | G9: 0 | H9: 0 | I9: 0.01 | J9: 0.02 | K9: 0.04 | L9: 0 | M9: 201.03 | N9: 395.938 | O9: 767.385 | P9: 0 | Q9: 0 | R9: 0 | S9: 0 | T9: 0 | U9: 0 | V9: 0 | W9: 0 | X9: 0 | Y9: 0 | Z9: 0 | AA9: 0 | AB9: faible | AC9: recherche/fiches/R05_allouer_les_effectifs_de_l_etat_territorial_selo.md
A10: R06 | B10: Resserrer les administrations centrales au-delà du PLF 2027 | C10: V_FPE_AUTRES | D10: 12 | E10: 1 | F10: 0 | G10: 0 | H10: 0 | I10: 0.01 | J10: 0.02 | K10: 0.04 | L10: 0 | M10: 199.02 | N10: 388.019 | O10: 736.69 | P10: 0 | Q10: 0 | R10: 0 | S10: 0 | T10: 0 | U10: 0 | V10: 0 | W10: 0 | X10: 0 | Y10: 0 | Z10: 0 | AA10: 0 | AB10: faible | AC10: recherche/fiches/R06_resserrer_les_administrations_centrales_au_dela_.md
A11: R07 | B11: Réutiliser les données détenues et ne plus redemander les pièces | C11: V_FPE_AUTRES | D11: 20 | E11: 1 | F11: 0 | G11: 0 | H11: 0.005 | I11: 0.01 | J11: 0.02 | K11: 0.03 | L11: 101.536 | M11: 197.03 | N11: 380.259 | O11: 530.417 | P11: 0 | Q11: 0 | R11: 0 | S11: 0 | T11: 0 | U11: 0 | V11: 0 | W11: 0 | X11: 0 | Y11: 0 | Z11: 0 | AA11: 0 | AB11: moyen | AC11: recherche/fiches/R07_reutiliser_les_donnees_detenues_et_ne_plus_redem.md
A12: R08 | B12: Supprimer les procédures et obligations d'information sans usage | C12: V_FPE_AUTRES | D12: 21 | E12: 1 | F12: 0 | G12: 0 | H12: 0 | I12: 0.005 | J12: 0.015 | K12: 0.03 | L12: 0 | M12: 97.53 | N12: 279.49 | O12: 514.504 | P12: 0 | Q12: 0 | R12: 0 | S12: 0 | T12: 0 | U12: 0 | V12: 0 | W12: 0 | X12: 0 | Y12: 0 | Z12: 0 | AA12: 0 | AB12: faible | AC12: recherche/fiches/R08_supprimer_les_procedures_et_obligations_d_inform.md
A13: R09 | B13: Créer des services partagés de gestion pour les opérateurs | C13: V_FPE_AUTRES | D13: 30 | E13: 1 | F13: 0 | G13: 0 | H13: 0.005 | I13: 0.015 | J13: 0.03 | K13: 0.04 | L13: 101.028 | M13: 291.126 | N13: 550.596 | O13: 665.425 | P13: 0 | Q13: 0 | R13: 0 | S13: 0 | T13: 0 | U13: 0 | V13: 0 | W13: 0 | X13: 0 | Y13: 0 | Z13: 0 | AA13: 0 | AB13: faible | AC13: recherche/fiches/R09_creer_des_services_partages_de_gestion_pour_les_.md
... A31: R24 | B31: Automatiser le traitement des dossiers de prestations | C31: V_OPS | D31: 40 | E31: 1 | F31: 0 | G31: 0 | H31: 0 | I31: 0.01 | J31: 0.03 | K31: 0.05 | L31: 0 | M31: 43.42 | N31: 43.42 | O31: 43.42 | P31: 0 | Q31: 1.708 | R31: 1.708 | S31: 1.708 | T31: 0 | U31: 0 | V31: 0 | W31: 0 | X31: 0 | Y31: 0 | Z31: 0 | AA31: 0 | AB31: faible | AC31: recherche/fiches/R24_automatiser_le_traitement_des_dossiers_de_presta.md

Sheet Calcul_prudent
A1: id | B1: vivier | C1: ordre | D1: base ETP | E1: plafond | F1: taux effectif | G1: cumul cibles précédentes | H1: cible ETP | I1: non-remplacement demandé | J1: capacité départs vivier | K1: cumul NR précédents | L1: NR réalisé | M1: redéployés | N1: coût unitaire (k€) | O1: économie salariale RP (M€) | P1: éco. fonctionnement (M€) | Q1: coût récurrent (M€) | R1: recettes (M€) | S1: net RP (M€) | T1: consolidé APU RP (M€) | U1: investissement (M€)
A2: =Reformes!A2 | B2: =Reformes!C2 | C2: =Reformes!D2 | D2: =VLOOKUP(B2,Viviers!$A$2:$I$9,3,FALSE) | E2: =VLOOKUP(B2,Viviers!$A$2:$I$9,5,FALSE) | F2: =MIN(1,Reformes!H2*Hypotheses!$B$5) | G2: =0 | H2: =MAX(0,MIN(F2*(D2-G2),E2*D2-G2)) | I2: =H2*Reformes!E2 | J2: =VLOOKUP(B2,Viviers!$A$2:$I$9,9,FALSE) | K2: =0 | L2: =MIN(I2,MAX(0,J2-K2)) | M2: =H2*Reformes!F2 | N2: =MIN(VLOOKUP(VLOOKUP(B2,Viviers!$A$2:$I$9,2,FALSE),Hypotheses!$A$11:$C$15,3,FALSE),VLOOKUP(VLOOKUP(B2,Viviers!$A$2:$I$9,2,FALSE),Hypotheses!$A$11:$C$15,2,FALSE)*(1+Hypotheses!$B$3)^(Hypotheses!$B$2/2))*Hypotheses!$B$7 | O2: =L2*N2/1000 | P2: =Reformes!T2 | Q2: =IF(Reformes!G2=1,Reformes!P2*IF(I2>0,L2/I2,0),Reformes!P2) | R2: =Reformes!X2 | S2: =O2+P2-Q2+R2 | T2: =O2*Hypotheses!$B$4+P2-Q2+R2 | U2: =Reformes!L2*Hypotheses!$B$8
A3: =Reformes!A3 | B3: =Reformes!C3 | C3: =Reformes!D3 | D3: =VLOOKUP(B3,Viviers!$A$2:$I$9,3,FALSE) | E3: =VLOOKUP(B3,Viviers!$A$2:$I$9,5,FALSE) | F3: =MIN(1,Reformes!H3*Hypotheses!$B$5) | G3: =IF(B3=B2,G2+H2,0) | H3: =MAX(0,MIN(F3*(D3-G3),E3*D3-G3)) | I3: =H3*Reformes!E3 | J3: =VLOOKUP(B3,Viviers!$A$2:$I$9,9,FALSE) | K3: =IF(B3=B2,K2+L2,0) | L3: =MIN(I3,MAX(0,J3-K3)) | M3: =H3*Reformes!F3 | N3: =MIN(VLOOKUP(VLOOKUP(B3,Viviers!$A$2:$I$9,2,FALSE),Hypotheses!$A$11:$C$15,3,FALSE),VLOOKUP(VLOOKUP(B3,Viviers!$A$2:$I$9,2,FALSE),Hypotheses!$A$11:$C$15,2,FALSE)*(1+Hypotheses!$B$3)^(Hypotheses!$B$2/2))*Hypotheses!$B$7 | O3: =L3*N3/1000 | P3: =Reformes!T3 | Q3: =IF(Reformes!G3=1,Reformes!P3*IF(I3>0,L3/I3,0),Reformes!P3) | R3: =Reformes!X3 | S3: =O3+P3-Q3+R3 | T3: =O3*Hypotheses!$B$4+P3-Q3+R3 | U3: =Reformes!L3*Hypotheses!$B$8
A4: =Reformes!A4 | B4: =Reformes!C4 | C4: =Reformes!D4 | D4: =VLOOKUP(B4,Viviers!$A$2:$I$9,3,FALSE) | E4: =VLOOKUP(B4,Viviers!$A$2:$I$9,5,FALSE) | F4: =MIN(1,Reformes!H4*Hypotheses!$B$5) | G4: =IF(B4=B3,G3+H3,0) | H4: =MAX(0,MIN(F4*(D4-G4),E4*D4-G4)) | I4: =H4*Reformes!E4 | J4: =VLOOKUP(B4,Viviers!$A$2:$I$9,9,FALSE) | K4: =IF(B4=B3,K3+L3,0) | L4: =MIN(I4,MAX(0,J4-K4)) | M4: =H4*Reformes!F4 | N4: =MIN(VLOOKUP(VLOOKUP(B4,Viviers!$A$2:$I$9,2,FALSE),Hypotheses!$A$11:$C$15,3,FALSE),VLOOKUP(VLOOKUP(B4,Viviers!$A$2:$I$9,2,FALSE),Hypotheses!$A$11:$C$15,2,FALSE)*(1+Hypotheses!$B$3)^(Hypotheses!$B$2/2))*Hypotheses!$B$7 | O4: =L4*N4/1000 | P4: =Reformes!T4 | Q4: =IF(Reformes!G4=1,Reformes!P4*IF(I4>0,L4/I4,0),Reformes!P4) | R4: =Reformes!X4 | S4: =O4+P4-Q4+R4 | T4: =O4*Hypotheses!$B$4+P4-Q4+R4 | U4: =Reformes!L4*Hypotheses!$B$8
A5: =Reformes!A5 | B5: =Reformes!C5 | C5: =Reformes!D5 | D5: =VLOOKUP(B5,Viviers!$A$2:$I$9,3,FALSE) | E5: =VLOOKUP(B5,Viviers!$A$2:$I$9,5,FALSE) | F5: =MIN(1,Reformes!H5*Hypotheses!$B$5) | G5: =IF(B5=B4,G4+H4,0) | H5: =MAX(0,MIN(F5*(D5-G5),E5*D5-G5)) | I5: =H5*Reformes!E5 | J5: =VLOOKUP(B5,Viviers!$A$2:$I$9,9,FALSE) | K5: =IF(B5=B4,K4+L4,0) | L5: =MIN(I5,MAX(0,J5-K5)) | M5: =H5*Reformes!F5 | N5: =MIN(VLOOKUP(VLOOKUP(B5,Viviers!$A$2:$I$9,2,FALSE),Hypotheses!$A$11:$C$15,3,FALSE),VLOOKUP(VLOOKUP(B5,Viviers!$A$2:$I$9,2,FALSE),Hypotheses!$A$11:$C$15,2,FALSE)*(1+Hypotheses!$B$3)^(Hypotheses!$B$2/2))*Hypotheses!$B$7 | O5: =L5*N5/1000 | P5: =Reformes!T5 | Q5: =IF(Reformes!G5=1,Reformes!P5*IF(I5>0,L5/I5,0),Reformes!P5) | R5: =Reformes!X5 | S5: =O5+P5-Q5+R5 | T5: =O5*Hypotheses!$B$4+P5-Q5+R5 | U5: =Reformes!L5*Hypotheses!$B$8
A6: =Reformes!A6 | B6: =Reformes!C6 | C6: =Reformes!D6 | D6: =VLOOKUP(B6,Viviers!$A$2:$I$9,3,FALSE) | E6: =VLOOKUP(B6,Viviers!$A$2:$I$9,5,FALSE) | F6: =MIN(1,Reformes!H6*Hypotheses!$B$5) | G6: =IF(B6=B5,G5+H5,0) | H6: =MAX(0,MIN(F6*(D6-G6),E6*D6-G6)) | I6: =H6*Reformes!E6 | J6: =VLOOKUP(B6,Viviers!$A$2:$I$9,9,FALSE) | K6: =IF(B6=B5,K5+L5,0) | L6: =MIN(I6,MAX(0,J6-K6)) | M6: =H6*Reformes!F6 | N6: =MIN(VLOOKUP(VLOOKUP(B6,Viviers!$A$2:$I$9,2,FALSE),Hypotheses!$A$11:$C$15,3,FALSE),VLOOKUP(VLOOKUP(B6,Viviers!$A$2:$I$9,2,FALSE),Hypotheses!$A$11:$C$15,2,FALSE)*(1+Hypotheses!$B$3)^(Hypotheses!$B$2/2))*Hypotheses!$B$7 | O6: =L6*N6/1000 | P6: =Reformes!T6 | Q6: =IF(Reformes!G6=1,Reformes!P6*IF(I6>0,L6/I6,0),Reformes!P6) | R6: =Reformes!X6 | S6: =O6+P6-Q6+R6 | T6: =O6*Hypotheses!$B$4+P6-Q6+R6 | U6: =Reformes!L6*Hypotheses!$B$8
A7: =Reformes!A7 | B7: =Reformes!C7 | C7: =Reformes!D7 | D7: =VLOOKUP(B7,Viviers!$A$2:$I$9,3,FALSE) | E7: =VLOOKUP(B7,Viviers!$A$2:$I$9,5,FALSE) | F7: =MIN(1,Reformes!H7*Hypotheses!$B$5) | G7: =IF(B7=B6,G6+H6,0) | H7: =MAX(0,MIN(F7*(D7-G7),E7*D7-G7)) | I7: =H7*Reformes!E7 | J7: =VLOOKUP(B7,Viviers!$A$2:$I$9,9,FALSE) | K7: =IF(B7=B6,K6+L6,0) | L7: =MIN(I7,MAX(0,J7-K7)) | M7: =H7*Reformes!F7 | N7: =MIN(VLOOKUP(VLOOKUP(B7,Viviers!$A$2:$I$9,2,FALSE),Hypotheses!$A$11:$C$15,3,FALSE),VLOOKUP(VLOOKUP(B7,Viviers!$A$2:$I$9,2,FALSE),Hypotheses!$A$11:$C$15,2,FALSE)*(1+Hypotheses!$B$3)^(Hypotheses!$B$2/2))*Hypotheses!$B$7 | O7: =L7*N7/1000 | P7: =Reformes!T7 | Q7: =IF(Reformes!G7=1,Reformes!P7*IF(I7>0,L7/I7,0),Reformes!P7) | R7: =Reformes!X7 | S7: =O7+P7-Q7+R7 | T7: =O7*Hypotheses!$B$4+P7-Q7+R7 | U7: =Reformes!L7*Hypotheses!$B$8
A8: =Reformes!A8 | B8: =Reformes!C8 | C8: =Reformes!D8 | D8: =VLOOKUP(B8,Viviers!$A$2:$I$9,3,FALSE) | E8: =VLOOKUP(B8,Viviers!$A$2:$I$9,5,FALSE) | F8: =MIN(1,Reformes!H8*Hypotheses!$B$5) | G8: =IF(B8=B7,G7+H7,0) | H8: =MAX(0,MIN(F8*(D8-G8),E8*D8-G8)) | I8: =H8*Reformes!E8 | J8: =VLOOKUP(B8,Viviers!$A$2:$I$9,9,FALSE) | K8: =IF(B8=B7,K7+L7,0) | L8: =MIN(I8,MAX(0,J8-K8)) | M8: =H8*Reformes!F8 | N8: =MIN(VLOOKUP(VLOOKUP(B8,Viviers!$A$2:$I$9,2,FALSE),Hypotheses!$A$11:$C$15,3,FALSE),VLOOKUP(VLOOKUP(B8,Viviers!$A$2:$I$9,2,FALSE),Hypotheses!$A$11:$C$15,2,FALSE)*(1+Hypotheses!$B$3)^(Hypotheses!$B$2/2))*Hypotheses!$B$7 | O8: =L8*N8/1000 | P8: =Reformes!T8 | Q8: =IF(Reformes!G8=1,Reformes!P8*IF(I8>0,L8/I8,0),Reformes!P8) | R8: =Reformes!X8 | S8: =O8+P8-Q8+R8 | T8: =O8*Hypotheses!$B$4+P8-Q8+R8 | U8: =Reformes!L8*Hypotheses!$B$8
A9: =Reformes!A9 | B9: =Reformes!C9 | C9: =Reformes!D9 | D9: =VLOOKUP(B9,Viviers!$A$2:$I$9,3,FALSE) | E9: =VLOOKUP(B9,Viviers!$A$2:$I$9,5,FALSE) | F9: =MIN(1,Reformes!H9*Hypotheses!$B$5) | G9: =IF(B9=B8,G8+H8,0) | H9: =MAX(0,MIN(F9*(D9-G9),E9*D9-G9)) | I9: =H9*Reformes!E9 | J9: =VLOOKUP(B9,Viviers!$A$2:$I$9,9,FALSE) | K9: =IF(B9=B8,K8+L8,0) | L9: =MIN(I9,MAX(0,J9-K9)) | M9: =H9*Reformes!F9 | N9: =MIN(VLOOKUP(VLOOKUP(B9,Viviers!$A$2:$I$9,2,FALSE),Hypotheses!$A$11:$C$15,3,FALSE),VLOOKUP(VLOOKUP(B9,Viviers!$A$2:$I$9,2,FALSE),Hypotheses!$A$11:$C$15,2,FALSE)*(1+Hypotheses!$B$3)^(Hypotheses!$B$2/2))*Hypotheses!$B$7 | O9: =L9*N9/1000 | P9: =Reformes!T9 | Q9: =IF(Reformes!G9=1,Reformes!P9*IF(I9>0,L9/I9,0),Reformes!P9) | R9: =Reformes!X9 | S9: =O9+P9-Q9+R9 | T9: =O9*Hypotheses!$B$4+P9-Q9+R9 | U9: =Reformes!L9*Hypotheses!$B$8
A10: =Reformes!A10 | B10: =Reformes!C10 | C10: =Reformes!D10 | D10: =VLOOKUP(B10,Viviers!$A$2:$I$9,3,FALSE) | E10: =VLOOKUP(B10,Viviers!$A$2:$I$9,5,FALSE) | F10: =MIN(1,Reformes!H10*Hypotheses!$B$5) | G10: =IF(B10=B9,G9+H9,0) | H10: =MAX(0,MIN(F10*(D10-G10),E10*D10-G10)) | I10: =H10*Reformes!E10 | J10: =VLOOKUP(B10,Viviers!$A$2:$I$9,9,FALSE) | K10: =IF(B10=B9,K9+L9,0) | L10: =MIN(I10,MAX(0,J10-K10)) | M10: =H10*Reformes!F10 | N10: =MIN(VLOOKUP(VLOOKUP(B10,Viviers!$A$2:$I$9,2,FALSE),Hypotheses!$A$11:$C$15,3,FALSE),VLOOKUP(VLOOKUP(B10,Viviers!$A$2:$I$9,2,FALSE),Hypotheses!$A$11:$C$15,2,FALSE)*(1+Hypotheses!$B$3)^(Hypotheses!$B$2/2))*Hypotheses!$B$7 | O10: =L10*N10/1000 | P10: =Reformes!T10 | Q10: =IF(Reformes!G10=1,Reformes!P10*IF(I10>0,L10/I10,0),Reformes!P10) | R10: =Reformes!X10 | S10: =O10+P10-Q10+R10 | T10: =O10*Hypotheses!$B$4+P10-Q10+R10 | U10: =Reformes!L10*Hypotheses!$B$8
A11: =Reformes!A11 | B11: =Reformes!C11 | C11: =Reformes!D11 | D11: =VLOOKUP(B11,Viviers!$A$2:$I$9,3,FALSE) | E11: =VLOOKUP(B11,Viviers!$A$2:$I$9,5,FALSE) | F11: =MIN(1,Reformes!H11*Hypotheses!$B$5) | G11: =IF(B11=B10,G10+H10,0) | H11: =MAX(0,MIN(F11*(D11-G11),E11*D11-G11)) | I11: =H11*Reformes!E11 | J11: =VLOOKUP(B11,Viviers!$A$2:$I$9,9,FALSE) | K11: =IF(B11=B10,K10+L10,0) | L11: =MIN(I11,MAX(0,J11-K11)) | M11: =H11*Reformes!F11 | N11: =MIN(VLOOKUP(VLOOKUP(B11,Viviers!$A$2:$I$9,2,FALSE),Hypotheses!$A$11:$C$15,3,FALSE),VLOOKUP(VLOOKUP(B11,Viviers!$A$2:$I$9,2,FALSE),Hypotheses!$A$11:$C$15,2,FALSE)*(1+Hypotheses!$B$3)^(Hypotheses!$B$2/2))*Hypotheses!$B$7 | O11: =L11*N11/1000 | P11: =Reformes!T11 | Q11: =IF(Reformes!G11=1,Reformes!P11*IF(I11>0,L11/I11,0),Reformes!P11) | R11: =Reformes!X11 | S11: =O11+P11-Q11+R11 | T11: =O11*Hypotheses!$B$4+P11-Q11+R11 | U11: =Reformes!L11*Hypotheses!$B$8
A12: =Reformes!A12 | B12: =Reformes!C12 | C12: =Reformes!D12 | D12: =VLOOKUP(B12,Viviers!$A$2:$I$9,3,FALSE) | E12: =VLOOKUP(B12,Viviers!$A$2:$I$9,5,FALSE) | F12: =MIN(1,Reformes!H12*Hypotheses!$B$5) | G12: =IF(B12=B11,G11+H11,0) | H12: =MAX(0,MIN(F12*(D12-G12),E12*D12-G12)) | I12: =H12*Reformes!E12 | J12: =VLOOKUP(B12,Viviers!$A$2:$I$9,9,FALSE) | K12: =IF(B12=B11,K11+L11,0) | L12: =MIN(I12,MAX(0,J12-K12)) | M12: =H12*Reformes!F12 | N12: =MIN(VLOOKUP(VLOOKUP(B12,Viviers!$A$2:$I$9,2,FALSE),Hypotheses!$A$11:$C$15,3,FALSE),VLOOKUP(VLOOKUP(B12,Viviers!$A$2:$I$9,2,FALSE),Hypotheses!$A$11:$C$15,2,FALSE)*(1+Hypotheses!$B$3)^(Hypotheses!$B$2/2))*Hypotheses!$B$7 | O12: =L12*N12/1000 | P12: =Reformes!T12 | Q12: =IF(Reformes!G12=1,Reformes!P12*IF(I12>0,L12/I12,0),Reformes!P12) | R12: =Reformes!X12 | S12: =O12+P12-Q12+R12 | T12: =O12*Hypotheses!$B$4+P12-Q12+R12 | U12: =Reformes!L12*Hypotheses!$B$8
A13: =Reformes!A13 | B13: =Reformes!C13 | C13: =Reformes!D13 | D13: =VLOOKUP(B13,Viviers!$A$2:$I$9,3,FALSE) | E13: =VLOOKUP(B13,Viviers!$A$2:$I$9,5,FALSE) | F13: =MIN(1,Reformes!H13*Hypotheses!$B$5) | G13: =IF(B13=B12,G12+H12,0) | H13: =MAX(0,MIN(F13*(D13-G13),E13*D13-G13)) | I13: =H13*Reformes!E13 | J13: =VLOOKUP(B13,Viviers!$A$2:$I$9,9,FALSE) | K13: =IF(B13=B12,K12+L12,0) | L13: =MIN(I13,MAX(0,J13-K13)) | M13: =H13*Reformes!F13 | N13: =MIN(VLOOKUP(VLOOKUP(B13,Viviers!$A$2:$I$9,2,FALSE),Hypotheses!$A$11:$C$15,3,FALSE),VLOOKUP(VLOOKUP(B13,Viviers!$A$2:$I$9,2,FALSE),Hypotheses!$A$11:$C$15,2,FALSE)*(1+Hypotheses!$B$3)^(Hypotheses!$B$2/2))*Hypotheses!$B$7 | O13: =L13*N13/1000 | P13: =Reformes!T13 | Q13: =IF(Reformes!G13=1,Reformes!P13*IF(I13>0,L13/I13,0),Reformes!P13) | R13: =Reformes!X13 | S13: =O13+P13-Q13+R13 | T13: =O13*Hypotheses!$B$4+P13-Q13+R13 | U13: =Reformes!L13*Hypotheses!$B$8
A14: =Reformes!A14 | B14: =Reformes!C14 | C14: =Reformes!D14 | D14: =VLOOKUP(B14,Viviers!$A$2:$I$9,3,FALSE) | E14: =VLOOKUP(B14,Viviers!$A$2:$I$9,5,FALSE) | F14: =MIN(1,Reformes!H14*Hypotheses!$B$5) | G14: =IF(B14=B13,G13+H13,0) | H14: =MAX(0,MIN(F14*(D14-G14),E14*D14-G14)) | I14: =H14*Reformes!E14 | J14: =VLOOKUP(B14,Viviers!$A$2:$I$9,9,FALSE) | K14: =IF(B14=B13,K13+L13,0) | L14: =MIN(I14,MAX(0,J14-K14)) | M14: =H14*Reformes!F14 | N14: =MIN(VLOOKUP(VLOOKUP(B14,Viviers!$A$2:$I$9,2,FALSE),Hypotheses!$A$11:$C$15,3,FALSE),VLOOKUP(VLOOKUP(B14,Viviers!$A$2:$I$9,2,FALSE),Hypotheses!$A$11:$C$15,2,FALSE)*(1+Hypotheses!$B$3)^(Hypotheses!$B$2/2))*Hypotheses!$B$7 | O14: =L14*N14/1000 | P14: =Reformes!T14 | Q14: =IF(Reformes!G14=1,Reformes!P14*IF(I14>0,L14/I14,0),Reformes!P14) | R14: =Reformes!X14 | S14: =O14+P14-Q14+R14 | T14: =O14*Hypotheses!$B$4+P14-Q14+R14 | U14: =Reformes!L14*Hypotheses!$B$8
... A31: =Reformes!A31 | B31: =Reformes!C31 | C31: =Reformes!D31 | D31: =VLOOKUP(B31,Viviers!$A$2:$I$9,3,FALSE) | E31: =VLOOKUP(B31,Viviers!$A$2:$I$9,5,FALSE) | F31: =MIN(1,Reformes!H31*Hypotheses!$B$5) | G31: =IF(B31=B30,G30+H30,0) | H31: =MAX(0,MIN(F31*(D31-G31),E31*D31-G31)) | I31: =H31*Reformes!E31 | J31: =VLOOKUP(B31,Viviers!$A$2:$I$9,9,FALSE) | K31: =IF(B31=B30,K30+L30,0) | L31: =MIN(I31,MAX(0,J31-K31)) | M31: =H31*Reformes!F31 | N31: =MIN(VLOOKUP(VLOOKUP(B31,Viviers!$A$2:$I$9,2,FALSE),Hypotheses!$A$11:$C$15,3,FALSE),VLOOKUP(VLOOKUP(B31,Viviers!$A$2:$I$9,2,FALSE),Hypotheses!$A$11:$C$15,2,FALSE)*(1+Hypotheses!$B$3)^(Hypotheses!$B$2/2))*Hypotheses!$B$7 | O31: =L31*N31/1000 | P31: =Reformes!T31 | Q31: =IF(Reformes!G31=1,Reformes!P31*IF(I31>0,L31/I31,0),Reformes!P31) | R31: =Reformes!X31 | S31: =O31+P31-Q31+R31 | T31: =O31*Hypotheses!$B$4+P31-Q31+R31 | U31: =Reformes!L31*Hypotheses!$B$8
A32: Total | H32: =SUM(H2:H31) | L32: =SUM(L2:L31) | M32: =SUM(M2:M31) | O32: =SUM(O2:O31) | P32: =SUM(P2:P31) | Q32: =SUM(Q2:Q31) | R32: =SUM(R2:R31) | S32: =SUM(S2:S31) | T32: =SUM(T2:T31) | U32: =SUM(U2:U31)

Sheet Calcul_intermediaire
A1: id | B1: vivier | C1: ordre | D1: base ETP | E1: plafond | F1: taux effectif | G1: cumul cibles précédentes | H1: cible ETP | I1: non-remplacement demandé | J1: capacité départs vivier | K1: cumul NR précédents | L1: NR réalisé | M1: redéployés | N1: coût unitaire (k€) | O1: économie salariale RP (M€) | P1: éco. fonctionnement (M€) | Q1: coût récurrent (M€) | R1: recettes (M€) | S1: net RP (M€) | T1: consolidé APU RP (M€) | U1: investissement (M€)
A2: =Reformes!A2 | B2: =Reformes!C2 | C2: =Reformes!D2 | D2: =VLOOKUP(B2,Viviers!$A$2:$I$9,3,FALSE) | E2: =VLOOKUP(B2,Viviers!$A$2:$I$9,6,FALSE) | F2: =MIN(1,Reformes!I2*Hypotheses!$B$5) | G2: =0 | H2: =MAX(0,MIN(F2*(D2-G2),E2*D2-G2)) | I2: =H2*Reformes!E2 | J2: =VLOOKUP(B2,Viviers!$A$2:$I$9,9,FALSE) | K2: =0 | L2: =MIN(I2,MAX(0,J2-K2)) | M2: =H2*Reformes!F2 | N2: =MIN(VLOOKUP(VLOOKUP(B2,Viviers!$A$2:$I$9,2,FALSE),Hypotheses!$A$11:$C$15,3,FALSE),VLOOKUP(VLOOKUP(B2,Viviers!$A$2:$I$9,2,FALSE),Hypotheses!$A$11:$C$15,2,FALSE)*(1+Hypotheses!$B$3)^(Hypotheses!$B$2/2))*Hypotheses!$B$7 | O2: =L2*N2/1000 | P2: =Reformes!U2 | Q2: =IF(Reformes!G2=1,Reformes!Q2*IF(I2>0,L2/I2,0),Reformes!Q2) | R2: =Reformes!Y2 | S2: =O2+P2-Q2+R2 | T2: =O2*Hypotheses!$B$4+P2-Q2+R2 | U2: =Reformes!M2*Hypotheses!$B$8
A3: =Reformes!A3 | B3: =Reformes!C3 | C3: =Reformes!D3 | D3: =VLOOKUP(B3,Viviers!$A$2:$I$9,3,FALSE) | E3: =VLOOKUP(B3,Viviers!$A$2:$I$9,6,FALSE) | F3: =MIN(1,Reformes!I3*Hypotheses!$B$5) | G3: =IF(B3=B2,G2+H2,0) | H3: =MAX(0,MIN(F3*(D3-G3),E3*D3-G3)) | I3: =H3*Reformes!E3 | J3: =VLOOKUP(B3,Viviers!$A$2:$I$9,9,FALSE) | K3: =IF(B3=B2,K2+L2,0) | L3: =MIN(I3,MAX(0,J3-K3)) | M3: =H3*Reformes!F3 | N3: =MIN(VLOOKUP(VLOOKUP(B3,Viviers!$A$2:$I$9,2,FALSE),Hypotheses!$A$11:$C$15,3,FALSE),VLOOKUP(VLOOKUP(B3,Viviers!$A$2:$I$9,2,FALSE),Hypotheses!$A$11:$C$15,2,FALSE)*(1+Hypotheses!$B$3)^(Hypotheses!$B$2/2))*Hypotheses!$B$7 | O3: =L3*N3/1000 | P3: =Reformes!U3 | Q3: =IF(Reformes!G3=1,Reformes!Q3*IF(I3>0,L3/I3,0),Reformes!Q3) | R3: =Reformes!Y3 | S3: =O3+P3-Q3+R3 | T3: =O3*Hypotheses!$B$4+P3-Q3+R3 | U3: =Reformes!M3*Hypotheses!$B$8
A4: =Reformes!A4 | B4: =Reformes!C4 | C4: =Reformes!D4 | D4: =VLOOKUP(B4,Viviers!$A$2:$I$9,3,FALSE) | E4: =VLOOKUP(B4,Viviers!$A$2:$I$9,6,FALSE) | F4: =MIN(1,Reformes!I4*Hypotheses!$B$5) | G4: =IF(B4=B3,G3+H3,0) | H4: =MAX(0,MIN(F4*(D4-G4),E4*D4-G4)) | I4: =H4*Reformes!E4 | J4: =VLOOKUP(B4,Viviers!$A$2:$I$9,9,FALSE) | K4: =IF(B4=B3,K3+L3,0) | L4: =MIN(I4,MAX(0,J4-K4)) | M4: =H4*Reformes!F4 | N4: =MIN(VLOOKUP(VLOOKUP(B4,Viviers!$A$2:$I$9,2,FALSE),Hypotheses!$A$11:$C$15,3,FALSE),VLOOKUP(VLOOKUP(B4,Viviers!$A$2:$I$9,2,FALSE),Hypotheses!$A$11:$C$15,2,FALSE)*(1+Hypotheses!$B$3)^(Hypotheses!$B$2/2))*Hypotheses!$B$7 | O4: =L4*N4/1000 | P4: =Reformes!U4 | Q4: =IF(Reformes!G4=1,Reformes!Q4*IF(I4>0,L4/I4,0),Reformes!Q4) | R4: =Reformes!Y4 | S4: =O4+P4-Q4+R4 | T4: =O4*Hypotheses!$B$4+P4-Q4+R4 | U4: =Reformes!M4*Hypotheses!$B$8
A5: =Reformes!A5 | B5: =Reformes!C5 | C5: =Reformes!D5 | D5: =VLOOKUP(B5,Viviers!$A$2:$I$9,3,FALSE) | E5: =VLOOKUP(B5,Viviers!$A$2:$I$9,6,FALSE) | F5: =MIN(1,Reformes!I5*Hypotheses!$B$5) | G5: =IF(B5=B4,G4+H4,0) | H5: =MAX(0,MIN(F5*(D5-G5),E5*D5-G5)) | I5: =H5*Reformes!E5 | J5: =VLOOKUP(B5,Viviers!$A$2:$I$9,9,FALSE) | K5: =IF(B5=B4,K4+L4,0) | L5: =MIN(I5,MAX(0,J5-K5)) | M5: =H5*Reformes!F5 | N5: =MIN(VLOOKUP(VLOOKUP(B5,Viviers!$A$2:$I$9,2,FALSE),Hypotheses!$A$11:$C$15,3,FALSE),VLOOKUP(VLOOKUP(B5,Viviers!$A$2:$I$9,2,FALSE),Hypotheses!$A$11:$C$15,2,FALSE)*(1+Hypotheses!$B$3)^(Hypotheses!$B$2/2))*Hypotheses!$B$7 | O5: =L5*N5/1000 | P5: =Reformes!U5 | Q5: =IF(Reformes!G5=1,Reformes!Q5*IF(I5>0,L5/I5,0),Reformes!Q5) | R5: =Reformes!Y5 | S5: =O5+P5-Q5+R5 | T5: =O5*Hypotheses!$B$4+P5-Q5+R5 | U5: =Reformes!M5*Hypotheses!$B$8
A6: =Reformes!A6 | B6: =Reformes!C6 | C6: =Reformes!D6 | D6: =VLOOKUP(B6,Viviers!$A$2:$I$9,3,FALSE) | E6: =VLOOKUP(B6,Viviers!$A$2:$I$9,6,FALSE) | F6: =MIN(1,Reformes!I6*Hypotheses!$B$5) | G6: =IF(B6=B5,G5+H5,0) | H6: =MAX(0,MIN(F6*(D6-G6),E6*D6-G6)) | I6: =H6*Reformes!E6 | J6: =VLOOKUP(B6,Viviers!$A$2:$I$9,9,FALSE) | K6: =IF(B6=B5,K5+L5,0) | L6: =MIN(I6,MAX(0,J6-K6)) | M6: =H6*Reformes!F6 | N6: =MIN(VLOOKUP(VLOOKUP(B6,Viviers!$A$2:$I$9,2,FALSE),Hypotheses!$A$11:$C$15,3,FALSE),VLOOKUP(VLOOKUP(B6,Viviers!$A$2:$I$9,2,FALSE),Hypotheses!$A$11:$C$15,2,FALSE)*(1+Hypotheses!$B$3)^(Hypotheses!$B$2/2))*Hypotheses!$B$7 | O6: =L6*N6/1000 | P6: =Reformes!U6 | Q6: =IF(Reformes!G6=1,Reformes!Q6*IF(I6>0,L6/I6,0),Reformes!Q6) | R6: =Reformes!Y6 | S6: =O6+P6-Q6+R6 | T6: =O6*Hypotheses!$B$4+P6-Q6+R6 | U6: =Reformes!M6*Hypotheses!$B$8
A7: =Reformes!A7 | B7: =Reformes!C7 | C7: =Reformes!D7 | D7: =VLOOKUP(B7,Viviers!$A$2:$I$9,3,FALSE) | E7: =VLOOKUP(B7,Viviers!$A$2:$I$9,6,FALSE) | F7: =MIN(1,Reformes!I7*Hypotheses!$B$5) | G7: =IF(B7=B6,G6+H6,0) | H7: =MAX(0,MIN(F7*(D7-G7),E7*D7-G7)) | I7: =H7*Reformes!E7 | J7: =VLOOKUP(B7,Viviers!$A$2:$I$9,9,FALSE) | K7: =IF(B7=B6,K6+L6,0) | L7: =MIN(I7,MAX(0,J7-K7)) | M7: =H7*Reformes!F7 | N7: =MIN(VLOOKUP(VLOOKUP(B7,Viviers!$A$2:$I$9,2,FALSE),Hypotheses!$A$11:$C$15,3,FALSE),VLOOKUP(VLOOKUP(B7,Viviers!$A$2:$I$9,2,FALSE),Hypotheses!$A$11:$C$15,2,FALSE)*(1+Hypotheses!$B$3)^(Hypotheses!$B$2/2))*Hypotheses!$B$7 | O7: =L7*N7/1000 | P7: =Reformes!U7 | Q7: =IF(Reformes!G7=1,Reformes!Q7*IF(I7>0,L7/I7,0),Reformes!Q7) | R7: =Reformes!Y7 | S7: =O7+P7-Q7+R7 | T7: =O7*Hypotheses!$B$4+P7-Q7+R7 | U7: =Reformes!M7*Hypotheses!$B$8
A8: =Reformes!A8 | B8: =Reformes!C8 | C8: =Reformes!D8 | D8: =VLOOKUP(B8,Viviers!$A$2:$I$9,3,FALSE) | E8: =VLOOKUP(B8,Viviers!$A$2:$I$9,6,FALSE) | F8: =MIN(1,Reformes!I8*Hypotheses!$B$5) | G8: =IF(B8=B7,G7+H7,0) | H8: =MAX(0,MIN(F8*(D8-G8),E8*D8-G8)) | I8: =H8*Reformes!E8 | J8: =VLOOKUP(B8,Viviers!$A$2:$I$9,9,FALSE) | K8: =IF(B8=B7,K7+L7,0) | L8: =MIN(I8,MAX(0,J8-K8)) | M8: =H8*Reformes!F8 | N8: =MIN(VLOOKUP(VLOOKUP(B8,Viviers!$A$2:$I$9,2,FALSE),Hypotheses!$A$11:$C$15,3,FALSE),VLOOKUP(VLOOKUP(B8,Viviers!$A$2:$I$9,2,FALSE),Hypotheses!$A$11:$C$15,2,FALSE)*(1+Hypotheses!$B$3)^(Hypotheses!$B$2/2))*Hypotheses!$B$7 | O8: =L8*N8/1000 | P8: =Reformes!U8 | Q8: =IF(Reformes!G8=1,Reformes!Q8*IF(I8>0,L8/I8,0),Reformes!Q8) | R8: =Reformes!Y8 | S8: =O8+P8-Q8+R8 | T8: =O8*Hypotheses!$B$4+P8-Q8+R8 | U8: =Reformes!M8*Hypotheses!$B$8
A9: =Reformes!A9 | B9: =Reformes!C9 | C9: =Reformes!D9 | D9: =VLOOKUP(B9,Viviers!$A$2:$I$9,3,FALSE) | E9: =VLOOKUP(B9,Viviers!$A$2:$I$9,6,FALSE) | F9: =MIN(1,Reformes!I9*Hypotheses!$B$5) | G9: =IF(B9=B8,G8+H8,0) | H9: =MAX(0,MIN(F9*(D9-G9),E9*D9-G9)) | I9: =H9*Reformes!E9 | J9: =VLOOKUP(B9,Viviers!$A$2:$I$9,9,FALSE) | K9: =IF(B9=B8,K8+L8,0) | L9: =MIN(I9,MAX(0,J9-K9)) | M9: =H9*Reformes!F9 | N9: =MIN(VLOOKUP(VLOOKUP(B9,Viviers!$A$2:$I$9,2,FALSE),Hypotheses!$A$11:$C$15,3,FALSE),VLOOKUP(VLOOKUP(B9,Viviers!$A$2:$I$9,2,FALSE),Hypotheses!$A$11:$C$15,2,FALSE)*(1+Hypotheses!$B$3)^(Hypotheses!$B$2/2))*Hypotheses!$B$7 | O9: =L9*N9/1000 | P9: =Reformes!U9 | Q9: =IF(Reformes!G9=1,Reformes!Q9*IF(I9>0,L9/I9,0),Reformes!Q9) | R9: =Reformes!Y9 | S9: =O9+P9-Q9+R9 | T9: =O9*Hypotheses!$B$4+P9-Q9+R9 | U9: =Reformes!M9*Hypotheses!$B$8
A10: =Reformes!A10 | B10: =Reformes!C10 | C10: =Reformes!D10 | D10: =VLOOKUP(B10,Viviers!$A$2:$I$9,3,FALSE) | E10: =VLOOKUP(B10,Viviers!$A$2:$I$9,6,FALSE) | F10: =MIN(1,Reformes!I10*Hypotheses!$B$5) | G10: =IF(B10=B9,G9+H9,0) | H10: =MAX(0,MIN(F10*(D10-G10),E10*D10-G10)) | I10: =H10*Reformes!E10 | J10: =VLOOKUP(B10,Viviers!$A$2:$I$9,9,FALSE) | K10: =IF(B10=B9,K9+L9,0) | L10: =MIN(I10,MAX(0,J10-K10)) | M10: =H10*Reformes!F10 | N10: =MIN(VLOOKUP(VLOOKUP(B10,Viviers!$A$2:$I$9,2,FALSE),Hypotheses!$A$11:$C$15,3,FALSE),VLOOKUP(VLOOKUP(B10,Viviers!$A$2:$I$9,2,FALSE),Hypotheses!$A$11:$C$15,2,FALSE)*(1+Hypotheses!$B$3)^(Hypotheses!$B$2/2))*Hypotheses!$B$7 | O10: =L10*N10/1000 | P10: =Reformes!U10 | Q10: =IF(Reformes!G10=1,Reformes!Q10*IF(I10>0,L10/I10,0),Reformes!Q10) | R10: =Reformes!Y10 | S10: =O10+P10-Q10+R10 | T10: =O10*Hypotheses!$B$4+P10-Q10+R10 | U10: =Reformes!M10*Hypotheses!$B$8
A11: =Reformes!A11 | B11: =Reformes!C11 | C11: =Reformes!D11 | D11: =VLOOKUP(B11,Viviers!$A$2:$I$9,3,FALSE) | E11: =VLOOKUP(B11,Viviers!$A$2:$I$9,6,FALSE) | F11: =MIN(1,Reformes!I11*Hypotheses!$B$5) | G11: =IF(B11=B10,G10+H10,0) | H11: =MAX(0,MIN(F11*(D11-G11),E11*D11-G11)) | I11: =H11*Reformes!E11 | J11: =VLOOKUP(B11,Viviers!$A$2:$I$9,9,FALSE) | K11: =IF(B11=B10,K10+L10,0) | L11: =MIN(I11,MAX(0,J11-K11)) | M11: =H11*Reformes!F11 | N11: =MIN(VLOOKUP(VLOOKUP(B11,Viviers!$A$2:$I$9,2,FALSE),Hypotheses!$A$11:$C$15,3,FALSE),VLOOKUP(VLOOKUP(B11,Viviers!$A$2:$I$9,2,FALSE),Hypotheses!$A$11:$C$15,2,FALSE)*(1+Hypotheses!$B$3)^(Hypotheses!$B$2/2))*Hypotheses!$B$7 | O11: =L11*N11/1000 | P11: =Reformes!U11 | Q11: =IF(Reformes!G11=1,Reformes!Q11*IF(I11>0,L11/I11,0),Reformes!Q11) | R11: =Reformes!Y11 | S11: =O11+P11-Q11+R11 | T11: =O11*Hypotheses!$B$4+P11-Q11+R11 | U11: =Reformes!M11*Hypotheses!$B$8
A12: =Reformes!A12 | B12: =Reformes!C12 | C12: =Reformes!D12 | D12: =VLOOKUP(B12,Viviers!$A$2:$I$9,3,FALSE) | E12: =VLOOKUP(B12,Viviers!$A$2:$I$9,6,FALSE) | F12: =MIN(1,Reformes!I12*Hypotheses!$B$5) | G12: =IF(B12=B11,G11+H11,0) | H12: =MAX(0,MIN(F12*(D12-G12),E12*D12-G12)) | I12: =H12*Reformes!E12 | J12: =VLOOKUP(B12,Viviers!$A$2:$I$9,9,FALSE) | K12: =IF(B12=B11,K11+L11,0) | L12: =MIN(I12,MAX(0,J12-K12)) | M12: =H12*Reformes!F12 | N12: =MIN(VLOOKUP(VLOOKUP(B12,Viviers!$A$2:$I$9,2,FALSE),Hypotheses!$A$11:$C$15,3,FALSE),VLOOKUP(VLOOKUP(B12,Viviers!$A$2:$I$9,2,FALSE),Hypotheses!$A$11:$C$15,2,FALSE)*(1+Hypotheses!$B$3)^(Hypotheses!$B$2/2))*Hypotheses!$B$7 | O12: =L12*N12/1000 | P12: =Reformes!U12 | Q12: =IF(Reformes!G12=1,Reformes!Q12*IF(I12>0,L12/I12,0),Reformes!Q12) | R12: =Reformes!Y12 | S12: =O12+P12-Q12+R12 | T12: =O12*Hypotheses!$B$4+P12-Q12+R12 | U12: =Reformes!M12*Hypotheses!$B$8
A13: =Reformes!A13 | B13: =Reformes!C13 | C13: =Reformes!D13 | D13: =VLOOKUP(B13,Viviers!$A$2:$I$9,3,FALSE) | E13: =VLOOKUP(B13,Viviers!$A$2:$I$9,6,FALSE) | F13: =MIN(1,Reformes!I13*Hypotheses!$B$5) | G13: =IF(B13=B12,G12+H12,0) | H13: =MAX(0,MIN(F13*(D13-G13),E13*D13-G13)) | I13: =H13*Reformes!E13 | J13: =VLOOKUP(B13,Viviers!$A$2:$I$9,9,FALSE) | K13: =IF(B13=B12,K12+L12,0) | L13: =MIN(I13,MAX(0,J13-K13)) | M13: =H13*Reformes!F13 | N13: =MIN(VLOOKUP(VLOOKUP(B13,Viviers!$A$2:$I$9,2,FALSE),Hypotheses!$A$11:$C$15,3,FALSE),VLOOKUP(VLOOKUP(B13,Viviers!$A$2:$I$9,2,FALSE),Hypotheses!$A$11:$C$15,2,FALSE)*(1+Hypotheses!$B$3)^(Hypotheses!$B$2/2))*Hypotheses!$B$7 | O13: =L13*N13/1000 | P13: =Reformes!U13 | Q13: =IF(Reformes!G13=1,Reformes!Q13*IF(I13>0,L13/I13,0),Reformes!Q13) | R13: =Reformes!Y13 | S13: =O13+P13-Q13+R13 | T13: =O13*Hypotheses!$B$4+P13-Q13+R13 | U13: =Reformes!M13*Hypotheses!$B$8
A14: =Reformes!A14 | B14: =Reformes!C14 | C14: =Reformes!D14 | D14: =VLOOKUP(B14,Viviers!$A$2:$I$9,3,FALSE) | E14: =VLOOKUP(B14,Viviers!$A$2:$I$9,6,FALSE) | F14: =MIN(1,Reformes!I14*Hypotheses!$B$5) | G14: =IF(B14=B13,G13+H13,0) | H14: =MAX(0,MIN(F14*(D14-G14),E14*D14-G14)) | I14: =H14*Reformes!E14 | J14: =VLOOKUP(B14,Viviers!$A$2:$I$9,9,FALSE) | K14: =IF(B14=B13,K13+L13,0) | L14: =MIN(I14,MAX(0,J14-K14)) | M14: =H14*Reformes!F14 | N14: =MIN(VLOOKUP(VLOOKUP(B14,Viviers!$A$2:$I$9,2,FALSE),Hypotheses!$A$11:$C$15,3,FALSE),VLOOKUP(VLOOKUP(B14,Viviers!$A$2:$I$9,2,FALSE),Hypotheses!$A$11:$C$15,2,FALSE)*(1+Hypotheses!$B$3)^(Hypotheses!$B$2/2))*Hypotheses!$B$7 | O14: =L14*N14/1000 | P14: =Reformes!U14 | Q14: =IF(Reformes!G14=1,Reformes!Q14*IF(I14>0,L14/I14,0),Reformes!Q14) | R14: =Reformes!Y14 | S14: =O14+P14-Q14+R14 | T14: =O14*Hypotheses!$B$4+P14-Q14+R14 | U14: =Reformes!M14*Hypotheses!$B$8
... A31: =Reformes!A31 | B31: =Reformes!C31 | C31: =Reformes!D31 | D31: =VLOOKUP(B31,Viviers!$A$2:$I$9,3,FALSE) | E31: =VLOOKUP(B31,Viviers!$A$2:$I$9,6,FALSE) | F31: =MIN(1,Reformes!I31*Hypotheses!$B$5) | G31: =IF(B31=B30,G30+H30,0) | H31: =MAX(0,MIN(F31*(D31-G31),E31*D31-G31)) | I31: =H31*Reformes!E31 | J31: =VLOOKUP(B31,Viviers!$A$2:$I$9,9,FALSE) | K31: =IF(B31=B30,K30+L30,0) | L31: =MIN(I31,MAX(0,J31-K31)) | M31: =H31*Reformes!F31 | N31: =MIN(VLOOKUP(VLOOKUP(B31,Viviers!$A$2:$I$9,2,FALSE),Hypotheses!$A$11:$C$15,3,FALSE),VLOOKUP(VLOOKUP(B31,Viviers!$A$2:$I$9,2,FALSE),Hypotheses!$A$11:$C$15,2,FALSE)*(1+Hypotheses!$B$3)^(Hypotheses!$B$2/2))*Hypotheses!$B$7 | O31: =L31*N31/1000 | P31: =Reformes!U31 | Q31: =IF(Reformes!G31=1,Reformes!Q31*IF(I31>0,L31/I31,0),Reformes!Q31) | R31: =Reformes!Y31 | S31: =O31+P31-Q31+R31 | T31: =O31*Hypotheses!$B$4+P31-Q31+R31 | U31: =Reformes!M31*Hypotheses!$B$8
A32: Total | H32: =SUM(H2:H31) | L32: =SUM(L2:L31) | M32: =SUM(M2:M31) | O32: =SUM(O2:O31) | P32: =SUM(P2:P31) | Q32: =SUM(Q2:Q31) | R32: =SUM(R2:R31) | S32: =SUM(S2:S31) | T32: =SUM(T2:T31) | U32: =SUM(U2:U31)

Sheet Calcul_ambitieux
A1: id | B1: vivier | C1: ordre | D1: base ETP | E1: plafond | F1: taux effectif | G1: cumul cibles précédentes | H1: cible ETP | I1: non-remplacement demandé | J1: capacité départs vivier | K1: cumul NR précédents | L1: NR réalisé | M1: redéployés | N1: coût unitaire (k€) | O1: économie salariale RP (M€) | P1: éco. fonctionnement (M€) | Q1: coût récurrent (M€) | R1: recettes (M€) | S1: net RP (M€) | T1: consolidé APU RP (M€) | U1: investissement (M€)
A2: =Reformes!A2 | B2: =Reformes!C2 | C2: =Reformes!D2 | D2: =VLOOKUP(B2,Viviers!$A$2:$I$9,3,FALSE) | E2: =VLOOKUP(B2,Viviers!$A$2:$I$9,7,FALSE) | F2: =MIN(1,Reformes!J2*Hypotheses!$B$5) | G2: =0 | H2: =MAX(0,MIN(F2*(D2-G2),E2*D2-G2)) | I2: =H2*Reformes!E2 | J2: =VLOOKUP(B2,Viviers!$A$2:$I$9,9,FALSE) | K2: =0 | L2: =MIN(I2,MAX(0,J2-K2)) | M2: =H2*Reformes!F2 | N2: =MIN(VLOOKUP(VLOOKUP(B2,Viviers!$A$2:$I$9,2,FALSE),Hypotheses!$A$11:$C$15,3,FALSE),VLOOKUP(VLOOKUP(B2,Viviers!$A$2:$I$9,2,FALSE),Hypotheses!$A$11:$C$15,2,FALSE)*(1+Hypotheses!$B$3)^(Hypotheses!$B$2/2))*Hypotheses!$B$7 | O2: =L2*N2/1000 | P2: =Reformes!V2 | Q2: =IF(Reformes!G2=1,Reformes!R2*IF(I2>0,L2/I2,0),Reformes!R2) | R2: =Reformes!Z2 | S2: =O2+P2-Q2+R2 | T2: =O2*Hypotheses!$B$4+P2-Q2+R2 | U2: =Reformes!N2*Hypotheses!$B$8
A3: =Reformes!A3 | B3: =Reformes!C3 | C3: =Reformes!D3 | D3: =VLOOKUP(B3,Viviers!$A$2:$I$9,3,FALSE) | E3: =VLOOKUP(B3,Viviers!$A$2:$I$9,7,FALSE) | F3: =MIN(1,Reformes!J3*Hypotheses!$B$5) | G3: =IF(B3=B2,G2+H2,0) | H3: =MAX(0,MIN(F3*(D3-G3),E3*D3-G3)) | I3: =H3*Reformes!E3 | J3: =VLOOKUP(B3,Viviers!$A$2:$I$9,9,FALSE) | K3: =IF(B3=B2,K2+L2,0) | L3: =MIN(I3,MAX(0,J3-K3)) | M3: =H3*Reformes!F3 | N3: =MIN(VLOOKUP(VLOOKUP(B3,Viviers!$A$2:$I$9,2,FALSE),Hypotheses!$A$11:$C$15,3,FALSE),VLOOKUP(VLOOKUP(B3,Viviers!$A$2:$I$9,2,FALSE),Hypotheses!$A$11:$C$15,2,FALSE)*(1+Hypotheses!$B$3)^(Hypotheses!$B$2/2))*Hypotheses!$B$7 | O3: =L3*N3/1000 | P3: =Reformes!V3 | Q3: =IF(Reformes!G3=1,Reformes!R3*IF(I3>0,L3/I3,0),Reformes!R3) | R3: =Reformes!Z3 | S3: =O3+P3-Q3+R3 | T3: =O3*Hypotheses!$B$4+P3-Q3+R3 | U3: =Reformes!N3*Hypotheses!$B$8
A4: =Reformes!A4 | B4: =Reformes!C4 | C4: =Reformes!D4 | D4: =VLOOKUP(B4,Viviers!$A$2:$I$9,3,FALSE) | E4: =VLOOKUP(B4,Viviers!$A$2:$I$9,7,FALSE) | F4: =MIN(1,Reformes!J4*Hypotheses!$B$5) | G4: =IF(B4=B3,G3+H3,0) | H4: =MAX(0,MIN(F4*(D4-G4),E4*D4-G4)) | I4: =H4*Reformes!E4 | J4: =VLOOKUP(B4,Viviers!$A$2:$I$9,9,FALSE) | K4: =IF(B4=B3,K3+L3,0) | L4: =MIN(I4,MAX(0,J4-K4)) | M4: =H4*Reformes!F4 | N4: =MIN(VLOOKUP(VLOOKUP(B4,Viviers!$A$2:$I$9,2,FALSE),Hypotheses!$A$11:$C$15,3,FALSE),VLOOKUP(VLOOKUP(B4,Viviers!$A$2:$I$9,2,FALSE),Hypotheses!$A$11:$C$15,2,FALSE)*(1+Hypotheses!$B$3)^(Hypotheses!$B$2/2))*Hypotheses!$B$7 | O4: =L4*N4/1000 | P4: =Reformes!V4 | Q4: =IF(Reformes!G4=1,Reformes!R4*IF(I4>0,L4/I4,0),Reformes!R4) | R4: =Reformes!Z4 | S4: =O4+P4-Q4+R4 | T4: =O4*Hypotheses!$B$4+P4-Q4+R4 | U4: =Reformes!N4*Hypotheses!$B$8
A5: =Reformes!A5 | B5: =Reformes!C5 | C5: =Reformes!D5 | D5: =VLOOKUP(B5,Viviers!$A$2:$I$9,3,FALSE) | E5: =VLOOKUP(B5,Viviers!$A$2:$I$9,7,FALSE) | F5: =MIN(1,Reformes!J5*Hypotheses!$B$5) | G5: =IF(B5=B4,G4+H4,0) | H5: =MAX(0,MIN(F5*(D5-G5),E5*D5-G5)) | I5: =H5*Reformes!E5 | J5: =VLOOKUP(B5,Viviers!$A$2:$I$9,9,FALSE) | K5: =IF(B5=B4,K4+L4,0) | L5: =MIN(I5,MAX(0,J5-K5)) | M5: =H5*Reformes!F5 | N5: =MIN(VLOOKUP(VLOOKUP(B5,Viviers!$A$2:$I$9,2,FALSE),Hypotheses!$A$11:$C$15,3,FALSE),VLOOKUP(VLOOKUP(B5,Viviers!$A$2:$I$9,2,FALSE),Hypotheses!$A$11:$C$15,2,FALSE)*(1+Hypotheses!$B$3)^(Hypotheses!$B$2/2))*Hypotheses!$B$7 | O5: =L5*N5/1000 | P5: =Reformes!V5 | Q5: =IF(Reformes!G5=1,Reformes!R5*IF(I5>0,L5/I5,0),Reformes!R5) | R5: =Reformes!Z5 | S5: =O5+P5-Q5+R5 | T5: =O5*Hypotheses!$B$4+P5-Q5+R5 | U5: =Reformes!N5*Hypotheses!$B$8
A6: =Reformes!A6 | B6: =Reformes!C6 | C6: =Reformes!D6 | D6: =VLOOKUP(B6,Viviers!$A$2:$I$9,3,FALSE) | E6: =VLOOKUP(B6,Viviers!$A$2:$I$9,7,FALSE) | F6: =MIN(1,Reformes!J6*Hypotheses!$B$5) | G6: =IF(B6=B5,G5+H5,0) | H6: =MAX(0,MIN(F6*(D6-G6),E6*D6-G6)) | I6: =H6*Reformes!E6 | J6: =VLOOKUP(B6,Viviers!$A$2:$I$9,9,FALSE) | K6: =IF(B6=B5,K5+L5,0) | L6: =MIN(I6,MAX(0,J6-K6)) | M6: =H6*Reformes!F6 | N6: =MIN(VLOOKUP(VLOOKUP(B6,Viviers!$A$2:$I$9,2,FALSE),Hypotheses!$A$11:$C$15,3,FALSE),VLOOKUP(VLOOKUP(B6,Viviers!$A$2:$I$9,2,FALSE),Hypotheses!$A$11:$C$15,2,FALSE)*(1+Hypotheses!$B$3)^(Hypotheses!$B$2/2))*Hypotheses!$B$7 | O6: =L6*N6/1000 | P6: =Reformes!V6 | Q6: =IF(Reformes!G6=1,Reformes!R6*IF(I6>0,L6/I6,0),Reformes!R6) | R6: =Reformes!Z6 | S6: =O6+P6-Q6+R6 | T6: =O6*Hypotheses!$B$4+P6-Q6+R6 | U6: =Reformes!N6*Hypotheses!$B$8
A7: =Reformes!A7 | B7: =Reformes!C7 | C7: =Reformes!D7 | D7: =VLOOKUP(B7,Viviers!$A$2:$I$9,3,FALSE) | E7: =VLOOKUP(B7,Viviers!$A$2:$I$9,7,FALSE) | F7: =MIN(1,Reformes!J7*Hypotheses!$B$5) | G7: =IF(B7=B6,G6+H6,0) | H7: =MAX(0,MIN(F7*(D7-G7),E7*D7-G7)) | I7: =H7*Reformes!E7 | J7: =VLOOKUP(B7,Viviers!$A$2:$I$9,9,FALSE) | K7: =IF(B7=B6,K6+L6,0) | L7: =MIN(I7,MAX(0,J7-K7)) | M7: =H7*Reformes!F7 | N7: =MIN(VLOOKUP(VLOOKUP(B7,Viviers!$A$2:$I$9,2,FALSE),Hypotheses!$A$11:$C$15,3,FALSE),VLOOKUP(VLOOKUP(B7,Viviers!$A$2:$I$9,2,FALSE),Hypotheses!$A$11:$C$15,2,FALSE)*(1+Hypotheses!$B$3)^(Hypotheses!$B$2/2))*Hypotheses!$B$7 | O7: =L7*N7/1000 | P7: =Reformes!V7 | Q7: =IF(Reformes!G7=1,Reformes!R7*IF(I7>0,L7/I7,0),Reformes!R7) | R7: =Reformes!Z7 | S7: =O7+P7-Q7+R7 | T7: =O7*Hypotheses!$B$4+P7-Q7+R7 | U7: =Reformes!N7*Hypotheses!$B$8
A8: =Reformes!A8 | B8: =Reformes!C8 | C8: =Reformes!D8 | D8: =VLOOKUP(B8,Viviers!$A$2:$I$9,3,FALSE) | E8: =VLOOKUP(B8,Viviers!$A$2:$I$9,7,FALSE) | F8: =MIN(1,Reformes!J8*Hypotheses!$B$5) | G8: =IF(B8=B7,G7+H7,0) | H8: =MAX(0,MIN(F8*(D8-G8),E8*D8-G8)) | I8: =H8*Reformes!E8 | J8: =VLOOKUP(B8,Viviers!$A$2:$I$9,9,FALSE) | K8: =IF(B8=B7,K7+L7,0) | L8: =MIN(I8,MAX(0,J8-K8)) | M8: =H8*Reformes!F8 | N8: =MIN(VLOOKUP(VLOOKUP(B8,Viviers!$A$2:$I$9,2,FALSE),Hypotheses!$A$11:$C$15,3,FALSE),VLOOKUP(VLOOKUP(B8,Viviers!$A$2:$I$9,2,FALSE),Hypotheses!$A$11:$C$15,2,FALSE)*(1+Hypotheses!$B$3)^(Hypotheses!$B$2/2))*Hypotheses!$B$7 | O8: =L8*N8/1000 | P8: =Reformes!V8 | Q8: =IF(Reformes!G8=1,Reformes!R8*IF(I8>0,L8/I8,0),Reformes!R8) | R8: =Reformes!Z8 | S8: =O8+P8-Q8+R8 | T8: =O8*Hypotheses!$B$4+P8-Q8+R8 | U8: =Reformes!N8*Hypotheses!$B$8
A9: =Reformes!A9 | B9: =Reformes!C9 | C9: =Reformes!D9 | D9: =VLOOKUP(B9,Viviers!$A$2:$I$9,3,FALSE) | E9: =VLOOKUP(B9,Viviers!$A$2:$I$9,7,FALSE) | F9: =MIN(1,Reformes!J9*Hypotheses!$B$5) | G9: =IF(B9=B8,G8+H8,0) | H9: =MAX(0,MIN(F9*(D9-G9),E9*D9-G9)) | I9: =H9*Reformes!E9 | J9: =VLOOKUP(B9,Viviers!$A$2:$I$9,9,FALSE) | K9: =IF(B9=B8,K8+L8,0) | L9: =MIN(I9,MAX(0,J9-K9)) | M9: =H9*Reformes!F9 | N9: =MIN(VLOOKUP(VLOOKUP(B9,Viviers!$A$2:$I$9,2,FALSE),Hypotheses!$A$11:$C$15,3,FALSE),VLOOKUP(VLOOKUP(B9,Viviers!$A$2:$I$9,2,FALSE),Hypotheses!$A$11:$C$15,2,FALSE)*(1+Hypotheses!$B$3)^(Hypotheses!$B$2/2))*Hypotheses!$B$7 | O9: =L9*N9/1000 | P9: =Reformes!V9 | Q9: =IF(Reformes!G9=1,Reformes!R9*IF(I9>0,L9/I9,0),Reformes!R9) | R9: =Reformes!Z9 | S9: =O9+P9-Q9+R9 | T9: =O9*Hypotheses!$B$4+P9-Q9+R9 | U9: =Reformes!N9*Hypotheses!$B$8
A10: =Reformes!A10 | B10: =Reformes!C10 | C10: =Reformes!D10 | D10: =VLOOKUP(B10,Viviers!$A$2:$I$9,3,FALSE) | E10: =VLOOKUP(B10,Viviers!$A$2:$I$9,7,FALSE) | F10: =MIN(1,Reformes!J10*Hypotheses!$B$5) | G10: =IF(B10=B9,G9+H9,0) | H10: =MAX(0,MIN(F10*(D10-G10),E10*D10-G10)) | I10: =H10*Reformes!E10 | J10: =VLOOKUP(B10,Viviers!$A$2:$I$9,9,FALSE) | K10: =IF(B10=B9,K9+L9,0) | L10: =MIN(I10,MAX(0,J10-K10)) | M10: =H10*Reformes!F10 | N10: =MIN(VLOOKUP(VLOOKUP(B10,Viviers!$A$2:$I$9,2,FALSE),Hypotheses!$A$11:$C$15,3,FALSE),VLOOKUP(VLOOKUP(B10,Viviers!$A$2:$I$9,2,FALSE),Hypotheses!$A$11:$C$15,2,FALSE)*(1+Hypotheses!$B$3)^(Hypotheses!$B$2/2))*Hypotheses!$B$7 | O10: =L10*N10/1000 | P10: =Reformes!V10 | Q10: =IF(Reformes!G10=1,Reformes!R10*IF(I10>0,L10/I10,0),Reformes!R10) | R10: =Reformes!Z10 | S10: =O10+P10-Q10+R10 | T10: =O10*Hypotheses!$B$4+P10-Q10+R10 | U10: =Reformes!N10*Hypotheses!$B$8
A11: =Reformes!A11 | B11: =Reformes!C11 | C11: =Reformes!D11 | D11: =VLOOKUP(B11,Viviers!$A$2:$I$9,3,FALSE) | E11: =VLOOKUP(B11,Viviers!$A$2:$I$9,7,FALSE) | F11: =MIN(1,Reformes!J11*Hypotheses!$B$5) | G11: =IF(B11=B10,G10+H10,0) | H11: =MAX(0,MIN(F11*(D11-G11),E11*D11-G11)) | I11: =H11*Reformes!E11 | J11: =VLOOKUP(B11,Viviers!$A$2:$I$9,9,FALSE) | K11: =IF(B11=B10,K10+L10,0) | L11: =MIN(I11,MAX(0,J11-K11)) | M11: =H11*Reformes!F11 | N11: =MIN(VLOOKUP(VLOOKUP(B11,Viviers!$A$2:$I$9,2,FALSE),Hypotheses!$A$11:$C$15,3,FALSE),VLOOKUP(VLOOKUP(B11,Viviers!$A$2:$I$9,2,FALSE),Hypotheses!$A$11:$C$15,2,FALSE)*(1+Hypotheses!$B$3)^(Hypotheses!$B$2/2))*Hypotheses!$B$7 | O11: =L11*N11/1000 | P11: =Reformes!V11 | Q11: =IF(Reformes!G11=1,Reformes!R11*IF(I11>0,L11/I11,0),Reformes!R11) | R11: =Reformes!Z11 | S11: =O11+P11-Q11+R11 | T11: =O11*Hypotheses!$B$4+P11-Q11+R11 | U11: =Reformes!N11*Hypotheses!$B$8
A12: =Reformes!A12 | B12: =Reformes!C12 | C12: =Reformes!D12 | D12: =VLOOKUP(B12,Viviers!$A$2:$I$9,3,FALSE) | E12: =VLOOKUP(B12,Viviers!$A$2:$I$9,7,FALSE) | F12: =MIN(1,Reformes!J12*Hypotheses!$B$5) | G12: =IF(B12=B11,G11+H11,0) | H12: =MAX(0,MIN(F12*(D12-G12),E12*D12-G12)) | I12: =H12*Reformes!E12 | J12: =VLOOKUP(B12,Viviers!$A$2:$I$9,9,FALSE) | K12: =IF(B12=B11,K11+L11,0) | L12: =MIN(I12,MAX(0,J12-K12)) | M12: =H12*Reformes!F12 | N12: =MIN(VLOOKUP(VLOOKUP(B12,Viviers!$A$2:$I$9,2,FALSE),Hypotheses!$A$11:$C$15,3,FALSE),VLOOKUP(VLOOKUP(B12,Viviers!$A$2:$I$9,2,FALSE),Hypotheses!$A$11:$C$15,2,FALSE)*(1+Hypotheses!$B$3)^(Hypotheses!$B$2/2))*Hypotheses!$B$7 | O12: =L12*N12/1000 | P12: =Reformes!V12 | Q12: =IF(Reformes!G12=1,Reformes!R12*IF(I12>0,L12/I12,0),Reformes!R12) | R12: =Reformes!Z12 | S12: =O12+P12-Q12+R12 | T12: =O12*Hypotheses!$B$4+P12-Q12+R12 | U12: =Reformes!N12*Hypotheses!$B$8
A13: =Reformes!A13 | B13: =Reformes!C13 | C13: =Reformes!D13 | D13: =VLOOKUP(B13,Viviers!$A$2:$I$9,3,FALSE) | E13: =VLOOKUP(B13,Viviers!$A$2:$I$9,7,FALSE) | F13: =MIN(1,Reformes!J13*Hypotheses!$B$5) | G13: =IF(B13=B12,G12+H12,0) | H13: =MAX(0,MIN(F13*(D13-G13),E13*D13-G13)) | I13: =H13*Reformes!E13 | J13: =VLOOKUP(B13,Viviers!$A$2:$I$9,9,FALSE) | K13: =IF(B13=B12,K12+L12,0) | L13: =MIN(I13,MAX(0,J13-K13)) | M13: =H13*Reformes!F13 | N13: =MIN(VLOOKUP(VLOOKUP(B13,Viviers!$A$2:$I$9,2,FALSE),Hypotheses!$A$11:$C$15,3,FALSE),VLOOKUP(VLOOKUP(B13,Viviers!$A$2:$I$9,2,FALSE),Hypotheses!$A$11:$C$15,2,FALSE)*(1+Hypotheses!$B$3)^(Hypotheses!$B$2/2))*Hypotheses!$B$7 | O13: =L13*N13/1000 | P13: =Reformes!V13 | Q13: =IF(Reformes!G13=1,Reformes!R13*IF(I13>0,L13/I13,0),Reformes!R13) | R13: =Reformes!Z13 | S13: =O13+P13-Q13+R13 | T13: =O13*Hypotheses!$B$4+P13-Q13+R13 | U13: =Reformes!N13*Hypotheses!$B$8
A14: =Reformes!A14 | B14: =Reformes!C14 | C14: =Reformes!D14 | D14: =VLOOKUP(B14,Viviers!$A$2:$I$9,3,FALSE) | E14: =VLOOKUP(B14,Viviers!$A$2:$I$9,7,FALSE) | F14: =MIN(1,Reformes!J14*Hypotheses!$B$5) | G14: =IF(B14=B13,G13+H13,0) | H14: =MAX(0,MIN(F14*(D14-G14),E14*D14-G14)) | I14: =H14*Reformes!E14 | J14: =VLOOKUP(B14,Viviers!$A$2:$I$9,9,FALSE) | K14: =IF(B14=B13,K13+L13,0) | L14: =MIN(I14,MAX(0,J14-K14)) | M14: =H14*Reformes!F14 | N14: =MIN(VLOOKUP(VLOOKUP(B14,Viviers!$A$2:$I$9,2,FALSE),Hypotheses!$A$11:$C$15,3,FALSE),VLOOKUP(VLOOKUP(B14,Viviers!$A$2:$I$9,2,FALSE),Hypotheses!$A$11:$C$15,2,FALSE)*(1+Hypotheses!$B$3)^(Hypotheses!$B$2/2))*Hypotheses!$B$7 | O14: =L14*N14/1000 | P14: =Reformes!V14 | Q14: =IF(Reformes!G14=1,Reformes!R14*IF(I14>0,L14/I14,0),Reformes!R14) | R14: =Reformes!Z14 | S14: =O14+P14-Q14+R14 | T14: =O14*Hypotheses!$B$4+P14-Q14+R14 | U14: =Reformes!N14*Hypotheses!$B$8
... A31: =Reformes!A31 | B31: =Reformes!C31 | C31: =Reformes!D31 | D31: =VLOOKUP(B31,Viviers!$A$2:$I$9,3,FALSE) | E31: =VLOOKUP(B31,Viviers!$A$2:$I$9,7,FALSE) | F31: =MIN(1,Reformes!J31*Hypotheses!$B$5) | G31: =IF(B31=B30,G30+H30,0) | H31: =MAX(0,MIN(F31*(D31-G31),E31*D31-G31)) | I31: =H31*Reformes!E31 | J31: =VLOOKUP(B31,Viviers!$A$2:$I$9,9,FALSE) | K31: =IF(B31=B30,K30+L30,0) | L31: =MIN(I31,MAX(0,J31-K31)) | M31: =H31*Reformes!F31 | N31: =MIN(VLOOKUP(VLOOKUP(B31,Viviers!$A$2:$I$9,2,FALSE),Hypotheses!$A$11:$C$15,3,FALSE),VLOOKUP(VLOOKUP(B31,Viviers!$A$2:$I$9,2,FALSE),Hypotheses!$A$11:$C$15,2,FALSE)*(1+Hypotheses!$B$3)^(Hypotheses!$B$2/2))*Hypotheses!$B$7 | O31: =L31*N31/1000 | P31: =Reformes!V31 | Q31: =IF(Reformes!G31=1,Reformes!R31*IF(I31>0,L31/I31,0),Reformes!R31) | R31: =Reformes!Z31 | S31: =O31+P31-Q31+R31 | T31: =O31*Hypotheses!$B$4+P31-Q31+R31 | U31: =Reformes!N31*Hypotheses!$B$8
A32: Total | H32: =SUM(H2:H31) | L32: =SUM(L2:L31) | M32: =SUM(M2:M31) | O32: =SUM(O2:O31) | P32: =SUM(P2:P31) | Q32: =SUM(Q2:Q31) | R32: =SUM(R2:R31) | S32: =SUM(S2:S31) | T32: =SUM(T2:T31) | U32: =SUM(U2:U31)

Sheet Calcul_radical
A1: id | B1: vivier | C1: ordre | D1: base ETP | E1: plafond | F1: taux effectif | G1: cumul cibles précédentes | H1: cible ETP | I1: non-remplacement demandé | J1: capacité départs vivier | K1: cumul NR précédents | L1: NR réalisé | M1: redéployés | N1: coût unitaire (k€) | O1: économie salariale RP (M€) | P1: éco. fonctionnement (M€) | Q1: coût récurrent (M€) | R1: recettes (M€) | S1: net RP (M€) | T1: consolidé APU RP (M€) | U1: investissement (M€)
A2: =Reformes!A2 | B2: =Reformes!C2 | C2: =Reformes!D2 | D2: =VLOOKUP(B2,Viviers!$A$2:$I$9,3,FALSE) | E2: =VLOOKUP(B2,Viviers!$A$2:$I$9,8,FALSE) | F2: =MIN(1,Reformes!K2*Hypotheses!$B$5) | G2: =0 | H2: =MAX(0,MIN(F2*(D2-G2),E2*D2-G2)) | I2: =H2*Reformes!E2 | J2: =VLOOKUP(B2,Viviers!$A$2:$I$9,9,FALSE) | K2: =0 | L2: =MIN(I2,MAX(0,J2-K2)) | M2: =H2*Reformes!F2 | N2: =MIN(VLOOKUP(VLOOKUP(B2,Viviers!$A$2:$I$9,2,FALSE),Hypotheses!$A$11:$C$15,3,FALSE),VLOOKUP(VLOOKUP(B2,Viviers!$A$2:$I$9,2,FALSE),Hypotheses!$A$11:$C$15,2,FALSE)*(1+Hypotheses!$B$3)^(Hypotheses!$B$2/2))*Hypotheses!$B$7 | O2: =L2*N2/1000 | P2: =Reformes!W2 | Q2: =IF(Reformes!G2=1,Reformes!S2*IF(I2>0,L2/I2,0),Reformes!S2) | R2: =Reformes!AA2 | S2: =O2+P2-Q2+R2 | T2: =O2*Hypotheses!$B$4+P2-Q2+R2 | U2: =Reformes!O2*Hypotheses!$B$8
A3: =Reformes!A3 | B3: =Reformes!C3 | C3: =Reformes!D3 | D3: =VLOOKUP(B3,Viviers!$A$2:$I$9,3,FALSE) | E3: =VLOOKUP(B3,Viviers!$A$2:$I$9,8,FALSE) | F3: =MIN(1,Reformes!K3*Hypotheses!$B$5) | G3: =IF(B3=B2,G2+H2,0) | H3: =MAX(0,MIN(F3*(D3-G3),E3*D3-G3)) | I3: =H3*Reformes!E3 | J3: =VLOOKUP(B3,Viviers!$A$2:$I$9,9,FALSE) | K3: =IF(B3=B2,K2+L2,0) | L3: =MIN(I3,MAX(0,J3-K3)) | M3: =H3*Reformes!F3 | N3: =MIN(VLOOKUP(VLOOKUP(B3,Viviers!$A$2:$I$9,2,FALSE),Hypotheses!$A$11:$C$15,3,FALSE),VLOOKUP(VLOOKUP(B3,Viviers!$A$2:$I$9,2,FALSE),Hypotheses!$A$11:$C$15,2,FALSE)*(1+Hypotheses!$B$3)^(Hypotheses!$B$2/2))*Hypotheses!$B$7 | O3: =L3*N3/1000 | P3: =Reformes!W3 | Q3: =IF(Reformes!G3=1,Reformes!S3*IF(I3>0,L3/I3,0),Reformes!S3) | R3: =Reformes!AA3 | S3: =O3+P3-Q3+R3 | T3: =O3*Hypotheses!$B$4+P3-Q3+R3 | U3: =Reformes!O3*Hypotheses!$B$8
A4: =Reformes!A4 | B4: =Reformes!C4 | C4: =Reformes!D4 | D4: =VLOOKUP(B4,Viviers!$A$2:$I$9,3,FALSE) | E4: =VLOOKUP(B4,Viviers!$A$2:$I$9,8,FALSE) | F4: =MIN(1,Reformes!K4*Hypotheses!$B$5) | G4: =IF(B4=B3,G3+H3,0) | H4: =MAX(0,MIN(F4*(D4-G4),E4*D4-G4)) | I4: =H4*Reformes!E4 | J4: =VLOOKUP(B4,Viviers!$A$2:$I$9,9,FALSE) | K4: =IF(B4=B3,K3+L3,0) | L4: =MIN(I4,MAX(0,J4-K4)) | M4: =H4*Reformes!F4 | N4: =MIN(VLOOKUP(VLOOKUP(B4,Viviers!$A$2:$I$9,2,FALSE),Hypotheses!$A$11:$C$15,3,FALSE),VLOOKUP(VLOOKUP(B4,Viviers!$A$2:$I$9,2,FALSE),Hypotheses!$A$11:$C$15,2,FALSE)*(1+Hypotheses!$B$3)^(Hypotheses!$B$2/2))*Hypotheses!$B$7 | O4: =L4*N4/1000 | P4: =Reformes!W4 | Q4: =IF(Reformes!G4=1,Reformes!S4*IF(I4>0,L4/I4,0),Reformes!S4) | R4: =Reformes!AA4 | S4: =O4+P4-Q4+R4 | T4: =O4*Hypotheses!$B$4+P4-Q4+R4 | U4: =Reformes!O4*Hypotheses!$B$8
A5: =Reformes!A5 | B5: =Reformes!C5 | C5: =Reformes!D5 | D5: =VLOOKUP(B5,Viviers!$A$2:$I$9,3,FALSE) | E5: =VLOOKUP(B5,Viviers!$A$2:$I$9,8,FALSE) | F5: =MIN(1,Reformes!K5*Hypotheses!$B$5) | G5: =IF(B5=B4,G4+H4,0) | H5: =MAX(0,MIN(F5*(D5-G5),E5*D5-G5)) | I5: =H5*Reformes!E5 | J5: =VLOOKUP(B5,Viviers!$A$2:$I$9,9,FALSE) | K5: =IF(B5=B4,K4+L4,0) | L5: =MIN(I5,MAX(0,J5-K5)) | M5: =H5*Reformes!F5 | N5: =MIN(VLOOKUP(VLOOKUP(B5,Viviers!$A$2:$I$9,2,FALSE),Hypotheses!$A$11:$C$15,3,FALSE),VLOOKUP(VLOOKUP(B5,Viviers!$A$2:$I$9,2,FALSE),Hypotheses!$A$11:$C$15,2,FALSE)*(1+Hypotheses!$B$3)^(Hypotheses!$B$2/2))*Hypotheses!$B$7 | O5: =L5*N5/1000 | P5: =Reformes!W5 | Q5: =IF(Reformes!G5=1,Reformes!S5*IF(I5>0,L5/I5,0),Reformes!S5) | R5: =Reformes!AA5 | S5: =O5+P5-Q5+R5 | T5: =O5*Hypotheses!$B$4+P5-Q5+R5 | U5: =Reformes!O5*Hypotheses!$B$8
A6: =Reformes!A6 | B6: =Reformes!C6 | C6: =Reformes!D6 | D6: =VLOOKUP(B6,Viviers!$A$2:$I$9,3,FALSE) | E6: =VLOOKUP(B6,Viviers!$A$2:$I$9,8,FALSE) | F6: =MIN(1,Reformes!K6*Hypotheses!$B$5) | G6: =IF(B6=B5,G5+H5,0) | H6: =MAX(0,MIN(F6*(D6-G6),E6*D6-G6)) | I6: =H6*Reformes!E6 | J6: =VLOOKUP(B6,Viviers!$A$2:$I$9,9,FALSE) | K6: =IF(B6=B5,K5+L5,0) | L6: =MIN(I6,MAX(0,J6-K6)) | M6: =H6*Reformes!F6 | N6: =MIN(VLOOKUP(VLOOKUP(B6,Viviers!$A$2:$I$9,2,FALSE),Hypotheses!$A$11:$C$15,3,FALSE),VLOOKUP(VLOOKUP(B6,Viviers!$A$2:$I$9,2,FALSE),Hypotheses!$A$11:$C$15,2,FALSE)*(1+Hypotheses!$B$3)^(Hypotheses!$B$2/2))*Hypotheses!$B$7 | O6: =L6*N6/1000 | P6: =Reformes!W6 | Q6: =IF(Reformes!G6=1,Reformes!S6*IF(I6>0,L6/I6,0),Reformes!S6) | R6: =Reformes!AA6 | S6: =O6+P6-Q6+R6 | T6: =O6*Hypotheses!$B$4+P6-Q6+R6 | U6: =Reformes!O6*Hypotheses!$B$8
A7: =Reformes!A7 | B7: =Reformes!C7 | C7: =Reformes!D7 | D7: =VLOOKUP(B7,Viviers!$A$2:$I$9,3,FALSE) | E7: =VLOOKUP(B7,Viviers!$A$2:$I$9,8,FALSE) | F7: =MIN(1,Reformes!K7*Hypotheses!$B$5) | G7: =IF(B7=B6,G6+H6,0) | H7: =MAX(0,MIN(F7*(D7-G7),E7*D7-G7)) | I7: =H7*Reformes!E7 | J7: =VLOOKUP(B7,Viviers!$A$2:$I$9,9,FALSE) | K7: =IF(B7=B6,K6+L6,0) | L7: =MIN(I7,MAX(0,J7-K7)) | M7: =H7*Reformes!F7 | N7: =MIN(VLOOKUP(VLOOKUP(B7,Viviers!$A$2:$I$9,2,FALSE),Hypotheses!$A$11:$C$15,3,FALSE),VLOOKUP(VLOOKUP(B7,Viviers!$A$2:$I$9,2,FALSE),Hypotheses!$A$11:$C$15,2,FALSE)*(1+Hypotheses!$B$3)^(Hypotheses!$B$2/2))*Hypotheses!$B$7 | O7: =L7*N7/1000 | P7: =Reformes!W7 | Q7: =IF(Reformes!G7=1,Reformes!S7*IF(I7>0,L7/I7,0),Reformes!S7) | R7: =Reformes!AA7 | S7: =O7+P7-Q7+R7 | T7: =O7*Hypotheses!$B$4+P7-Q7+R7 | U7: =Reformes!O7*Hypotheses!$B$8
